[2025-04-18T22:22:23.550+0800] {local_task_job_runner.py:123} INFO - ::group::Pre task execution logs
[2025-04-18T22:22:23.557+0800] {taskinstance.py:2614} INFO - Dependencies all met for dep_context=non-requeueable deps ti=<TaskInstance: reddit_yf_scraper.upload_yf_to_gcs manual__2025-04-18T14:21:40.546247+00:00 [queued]>
[2025-04-18T22:22:23.560+0800] {taskinstance.py:2614} INFO - Dependencies all met for dep_context=requeueable deps ti=<TaskInstance: reddit_yf_scraper.upload_yf_to_gcs manual__2025-04-18T14:21:40.546247+00:00 [queued]>
[2025-04-18T22:22:23.560+0800] {taskinstance.py:2867} INFO - Starting attempt 1 of 2
[2025-04-18T22:22:23.565+0800] {taskinstance.py:2890} INFO - Executing <Task(LocalFilesystemToGCSOperator): upload_yf_to_gcs> on 2025-04-18 14:21:40.546247+00:00
[2025-04-18T22:22:23.569+0800] {standard_task_runner.py:72} INFO - Started process 97968 to run task
[2025-04-18T22:22:23.573+0800] {standard_task_runner.py:104} INFO - Running: ['airflow', 'tasks', 'run', 'reddit_yf_scraper', 'upload_yf_to_gcs', 'manual__2025-04-18T14:21:40.546247+00:00', '--job-id', '540', '--raw', '--subdir', 'DAGS_FOLDER/dag.py', '--cfg-path', '/var/folders/2f/rw5w89ss6nl38qvq2cxrh29w0000gn/T/tmplgykz_63']
[2025-04-18T22:22:23.574+0800] {standard_task_runner.py:105} INFO - Job 540: Subtask upload_yf_to_gcs
[2025-04-18T22:22:23.593+0800] {task_command.py:467} INFO - Running <TaskInstance: reddit_yf_scraper.upload_yf_to_gcs manual__2025-04-18T14:21:40.546247+00:00 [running]> on host yueyaos-macbook-pro.local
[2025-04-18T22:22:23.620+0800] {taskinstance.py:3134} INFO - Exporting env vars: AIRFLOW_CTX_DAG_OWNER='airflow' AIRFLOW_CTX_DAG_ID='reddit_yf_scraper' AIRFLOW_CTX_TASK_ID='upload_yf_to_gcs' AIRFLOW_CTX_EXECUTION_DATE='2025-04-18T14:21:40.546247+00:00' AIRFLOW_CTX_TRY_NUMBER='1' AIRFLOW_CTX_DAG_RUN_ID='manual__2025-04-18T14:21:40.546247+00:00'
[2025-04-18T22:22:23.621+0800] {logging_mixin.py:190} INFO - Task instance is in running state
[2025-04-18T22:22:23.621+0800] {logging_mixin.py:190} INFO -  Previous state of the Task instance: queued
[2025-04-18T22:22:23.621+0800] {logging_mixin.py:190} INFO - Current task name:upload_yf_to_gcs state:running start_date:2025-04-18 14:22:23.557378+00:00
[2025-04-18T22:22:23.621+0800] {logging_mixin.py:190} INFO - Dag name:reddit_yf_scraper and current dag run status:running
[2025-04-18T22:22:23.621+0800] {taskinstance.py:732} INFO - ::endgroup::
[2025-04-18T22:22:23.624+0800] {connection.py:277} WARNING - Connection schemes (type: google_cloud_platform) shall not contain '_' according to RFC3986.
[2025-04-18T22:22:23.626+0800] {base.py:84} INFO - Retrieving connection 'google_cloud_default'
[2025-04-18T22:22:23.990+0800] {gcs.py:531} ERROR - Upload attempt of object: yf-test/AAPL_yf_20250418.csv from yf-test/AAPL_yf_20250418.csv has failed. Attempt: 1, max 1.
[2025-04-18T22:22:23.992+0800] {taskinstance.py:3313} ERROR - Task failed with exception
Traceback (most recent call last):
  File "/Users/yueyaoz/Downloads/IS3107-FinSum/.airflow/lib/python3.10/site-packages/google/cloud/storage/blob.py", line 2700, in _prep_and_do_upload
    created_json = self._do_upload(
  File "/Users/yueyaoz/Downloads/IS3107-FinSum/.airflow/lib/python3.10/site-packages/google/cloud/storage/blob.py", line 2506, in _do_upload
    response = self._do_multipart_upload(
  File "/Users/yueyaoz/Downloads/IS3107-FinSum/.airflow/lib/python3.10/site-packages/google/cloud/storage/blob.py", line 2007, in _do_multipart_upload
    response = upload.transmit(
  File "/Users/yueyaoz/Downloads/IS3107-FinSum/.airflow/lib/python3.10/site-packages/google/resumable_media/requests/upload.py", line 153, in transmit
    return _request_helpers.wait_and_retry(
  File "/Users/yueyaoz/Downloads/IS3107-FinSum/.airflow/lib/python3.10/site-packages/google/resumable_media/requests/_request_helpers.py", line 155, in wait_and_retry
    response = func()
  File "/Users/yueyaoz/Downloads/IS3107-FinSum/.airflow/lib/python3.10/site-packages/google/resumable_media/requests/upload.py", line 149, in retriable_request
    self._process_response(result)
  File "/Users/yueyaoz/Downloads/IS3107-FinSum/.airflow/lib/python3.10/site-packages/google/resumable_media/_upload.py", line 125, in _process_response
    _helpers.require_status_code(response, (http.client.OK,), self._get_status_code)
  File "/Users/yueyaoz/Downloads/IS3107-FinSum/.airflow/lib/python3.10/site-packages/google/resumable_media/_helpers.py", line 108, in require_status_code
    raise common.InvalidResponse(
google.resumable_media.common.InvalidResponse: ('Request failed with status code', 403, 'Expected one of', 200)

During handling of the above exception, another exception occurred:

Traceback (most recent call last):
  File "/Users/yueyaoz/Downloads/IS3107-FinSum/.airflow/lib/python3.10/site-packages/airflow/models/taskinstance.py", line 768, in _execute_task
    result = _execute_callable(context=context, **execute_callable_kwargs)
  File "/Users/yueyaoz/Downloads/IS3107-FinSum/.airflow/lib/python3.10/site-packages/airflow/models/taskinstance.py", line 734, in _execute_callable
    return ExecutionCallableRunner(
  File "/Users/yueyaoz/Downloads/IS3107-FinSum/.airflow/lib/python3.10/site-packages/airflow/utils/operator_helpers.py", line 252, in run
    return self.func(*args, **kwargs)
  File "/Users/yueyaoz/Downloads/IS3107-FinSum/.airflow/lib/python3.10/site-packages/airflow/models/baseoperator.py", line 424, in wrapper
    return func(self, *args, **kwargs)
  File "/Users/yueyaoz/Downloads/IS3107-FinSum/.airflow/lib/python3.10/site-packages/airflow/providers/google/cloud/transfers/local_to_gcs.py", line 115, in execute
    hook.upload(
  File "/Users/yueyaoz/Downloads/IS3107-FinSum/.airflow/lib/python3.10/site-packages/airflow/providers/google/cloud/hooks/gcs.py", line 570, in upload
    _call_with_retry(
  File "/Users/yueyaoz/Downloads/IS3107-FinSum/.airflow/lib/python3.10/site-packages/airflow/providers/google/cloud/hooks/gcs.py", line 538, in _call_with_retry
    raise e
  File "/Users/yueyaoz/Downloads/IS3107-FinSum/.airflow/lib/python3.10/site-packages/airflow/providers/google/cloud/hooks/gcs.py", line 528, in _call_with_retry
    f()
  File "/Users/yueyaoz/.pyenv/versions/3.10.13/lib/python3.10/contextlib.py", line 79, in inner
    return func(*args, **kwds)
  File "/Users/yueyaoz/Downloads/IS3107-FinSum/.airflow/lib/python3.10/site-packages/google/cloud/storage/blob.py", line 3006, in upload_from_filename
    self._handle_filename_and_upload(
  File "/Users/yueyaoz/Downloads/IS3107-FinSum/.airflow/lib/python3.10/site-packages/google/cloud/storage/blob.py", line 2884, in _handle_filename_and_upload
    self._prep_and_do_upload(
  File "/Users/yueyaoz/Downloads/IS3107-FinSum/.airflow/lib/python3.10/site-packages/google/cloud/storage/blob.py", line 2718, in _prep_and_do_upload
    _raise_from_invalid_response(exc)
  File "/Users/yueyaoz/Downloads/IS3107-FinSum/.airflow/lib/python3.10/site-packages/google/cloud/storage/blob.py", line 4908, in _raise_from_invalid_response
    raise exceptions.from_http_status(response.status_code, message, response=response)
google.api_core.exceptions.Forbidden: 403 POST https://storage.googleapis.com/upload/storage/v1/b/my-data-is3107/o?uploadType=multipart: {
  "error": {
    "code": 403,
    "message": "is3107-project@is3107zyy.iam.gserviceaccount.com does not have storage.objects.create access to the Google Cloud Storage object. Permission 'storage.objects.create' denied on resource (or it may not exist).",
    "errors": [
      {
        "message": "is3107-project@is3107zyy.iam.gserviceaccount.com does not have storage.objects.create access to the Google Cloud Storage object. Permission 'storage.objects.create' denied on resource (or it may not exist).",
        "domain": "global",
        "reason": "forbidden"
      }
    ]
  }
}
: ('Request failed with status code', 403, 'Expected one of', <HTTPStatus.OK: 200>)
[2025-04-18T22:22:24.007+0800] {logging_mixin.py:190} INFO - Task instance in failure state
[2025-04-18T22:22:24.008+0800] {logging_mixin.py:190} INFO - Task start:2025-04-18 14:22:23.557378+00:00 end:2025-04-18 14:22:24.007343+00:00 duration:0.449965
[2025-04-18T22:22:24.008+0800] {logging_mixin.py:190} INFO - Task:<Task(LocalFilesystemToGCSOperator): upload_yf_to_gcs> dag:<DAG: reddit_yf_scraper> dagrun:<DagRun reddit_yf_scraper @ 2025-04-18 14:21:40.546247+00:00: manual__2025-04-18T14:21:40.546247+00:00, state:running, queued_at: 2025-04-18 14:21:40.553925+00:00. externally triggered: True>
[2025-04-18T22:22:24.009+0800] {logging_mixin.py:190} INFO - Failure caused by 403 POST https://storage.googleapis.com/upload/storage/v1/b/my-data-is3107/o?uploadType=multipart: {
  "error": {
    "code": 403,
    "message": "is3107-project@is3107zyy.iam.gserviceaccount.com does not have storage.objects.create access to the Google Cloud Storage object. Permission 'storage.objects.create' denied on resource (or it may not exist).",
    "errors": [
      {
        "message": "is3107-project@is3107zyy.iam.gserviceaccount.com does not have storage.objects.create access to the Google Cloud Storage object. Permission 'storage.objects.create' denied on resource (or it may not exist).",
        "domain": "global",
        "reason": "forbidden"
      }
    ]
  }
}
: ('Request failed with status code', 403, 'Expected one of', <HTTPStatus.OK: 200>)
[2025-04-18T22:22:24.009+0800] {taskinstance.py:1226} INFO - Marking task as UP_FOR_RETRY. dag_id=reddit_yf_scraper, task_id=upload_yf_to_gcs, run_id=manual__2025-04-18T14:21:40.546247+00:00, execution_date=20250418T142140, start_date=20250418T142223, end_date=20250418T142224
[2025-04-18T22:22:24.022+0800] {taskinstance.py:341} INFO - ::group::Post task execution logs
[2025-04-18T22:22:24.022+0800] {standard_task_runner.py:124} ERROR - Failed to execute job 540 for task upload_yf_to_gcs (403 POST https://storage.googleapis.com/upload/storage/v1/b/my-data-is3107/o?uploadType=multipart: {
  "error": {
    "code": 403,
    "message": "is3107-project@is3107zyy.iam.gserviceaccount.com does not have storage.objects.create access to the Google Cloud Storage object. Permission 'storage.objects.create' denied on resource (or it may not exist).",
    "errors": [
      {
        "message": "is3107-project@is3107zyy.iam.gserviceaccount.com does not have storage.objects.create access to the Google Cloud Storage object. Permission 'storage.objects.create' denied on resource (or it may not exist).",
        "domain": "global",
        "reason": "forbidden"
      }
    ]
  }
}
: ('Request failed with status code', 403, 'Expected one of', <HTTPStatus.OK: 200>); 97968)
Traceback (most recent call last):
  File "/Users/yueyaoz/Downloads/IS3107-FinSum/.airflow/lib/python3.10/site-packages/google/cloud/storage/blob.py", line 2700, in _prep_and_do_upload
    created_json = self._do_upload(
  File "/Users/yueyaoz/Downloads/IS3107-FinSum/.airflow/lib/python3.10/site-packages/google/cloud/storage/blob.py", line 2506, in _do_upload
    response = self._do_multipart_upload(
  File "/Users/yueyaoz/Downloads/IS3107-FinSum/.airflow/lib/python3.10/site-packages/google/cloud/storage/blob.py", line 2007, in _do_multipart_upload
    response = upload.transmit(
  File "/Users/yueyaoz/Downloads/IS3107-FinSum/.airflow/lib/python3.10/site-packages/google/resumable_media/requests/upload.py", line 153, in transmit
    return _request_helpers.wait_and_retry(
  File "/Users/yueyaoz/Downloads/IS3107-FinSum/.airflow/lib/python3.10/site-packages/google/resumable_media/requests/_request_helpers.py", line 155, in wait_and_retry
    response = func()
  File "/Users/yueyaoz/Downloads/IS3107-FinSum/.airflow/lib/python3.10/site-packages/google/resumable_media/requests/upload.py", line 149, in retriable_request
    self._process_response(result)
  File "/Users/yueyaoz/Downloads/IS3107-FinSum/.airflow/lib/python3.10/site-packages/google/resumable_media/_upload.py", line 125, in _process_response
    _helpers.require_status_code(response, (http.client.OK,), self._get_status_code)
  File "/Users/yueyaoz/Downloads/IS3107-FinSum/.airflow/lib/python3.10/site-packages/google/resumable_media/_helpers.py", line 108, in require_status_code
    raise common.InvalidResponse(
google.resumable_media.common.InvalidResponse: ('Request failed with status code', 403, 'Expected one of', 200)

During handling of the above exception, another exception occurred:

Traceback (most recent call last):
  File "/Users/yueyaoz/Downloads/IS3107-FinSum/.airflow/lib/python3.10/site-packages/airflow/task/task_runner/standard_task_runner.py", line 117, in _start_by_fork
    ret = args.func(args, dag=self.dag)
  File "/Users/yueyaoz/Downloads/IS3107-FinSum/.airflow/lib/python3.10/site-packages/airflow/cli/cli_config.py", line 49, in command
    return func(*args, **kwargs)
  File "/Users/yueyaoz/Downloads/IS3107-FinSum/.airflow/lib/python3.10/site-packages/airflow/utils/cli.py", line 116, in wrapper
    return f(*args, **kwargs)
  File "/Users/yueyaoz/Downloads/IS3107-FinSum/.airflow/lib/python3.10/site-packages/airflow/cli/commands/task_command.py", line 483, in task_run
    task_return_code = _run_task_by_selected_method(args, _dag, ti)
  File "/Users/yueyaoz/Downloads/IS3107-FinSum/.airflow/lib/python3.10/site-packages/airflow/cli/commands/task_command.py", line 256, in _run_task_by_selected_method
    return _run_raw_task(args, ti)
  File "/Users/yueyaoz/Downloads/IS3107-FinSum/.airflow/lib/python3.10/site-packages/airflow/cli/commands/task_command.py", line 341, in _run_raw_task
    return ti._run_raw_task(
  File "/Users/yueyaoz/Downloads/IS3107-FinSum/.airflow/lib/python3.10/site-packages/airflow/utils/session.py", line 97, in wrapper
    return func(*args, session=session, **kwargs)
  File "/Users/yueyaoz/Downloads/IS3107-FinSum/.airflow/lib/python3.10/site-packages/airflow/models/taskinstance.py", line 3006, in _run_raw_task
    return _run_raw_task(
  File "/Users/yueyaoz/Downloads/IS3107-FinSum/.airflow/lib/python3.10/site-packages/airflow/models/taskinstance.py", line 274, in _run_raw_task
    TaskInstance._execute_task_with_callbacks(
  File "/Users/yueyaoz/Downloads/IS3107-FinSum/.airflow/lib/python3.10/site-packages/airflow/models/taskinstance.py", line 3161, in _execute_task_with_callbacks
    result = self._execute_task(context, task_orig)
  File "/Users/yueyaoz/Downloads/IS3107-FinSum/.airflow/lib/python3.10/site-packages/airflow/models/taskinstance.py", line 3185, in _execute_task
    return _execute_task(self, context, task_orig)
  File "/Users/yueyaoz/Downloads/IS3107-FinSum/.airflow/lib/python3.10/site-packages/airflow/models/taskinstance.py", line 768, in _execute_task
    result = _execute_callable(context=context, **execute_callable_kwargs)
  File "/Users/yueyaoz/Downloads/IS3107-FinSum/.airflow/lib/python3.10/site-packages/airflow/models/taskinstance.py", line 734, in _execute_callable
    return ExecutionCallableRunner(
  File "/Users/yueyaoz/Downloads/IS3107-FinSum/.airflow/lib/python3.10/site-packages/airflow/utils/operator_helpers.py", line 252, in run
    return self.func(*args, **kwargs)
  File "/Users/yueyaoz/Downloads/IS3107-FinSum/.airflow/lib/python3.10/site-packages/airflow/models/baseoperator.py", line 424, in wrapper
    return func(self, *args, **kwargs)
  File "/Users/yueyaoz/Downloads/IS3107-FinSum/.airflow/lib/python3.10/site-packages/airflow/providers/google/cloud/transfers/local_to_gcs.py", line 115, in execute
    hook.upload(
  File "/Users/yueyaoz/Downloads/IS3107-FinSum/.airflow/lib/python3.10/site-packages/airflow/providers/google/cloud/hooks/gcs.py", line 570, in upload
    _call_with_retry(
  File "/Users/yueyaoz/Downloads/IS3107-FinSum/.airflow/lib/python3.10/site-packages/airflow/providers/google/cloud/hooks/gcs.py", line 538, in _call_with_retry
    raise e
  File "/Users/yueyaoz/Downloads/IS3107-FinSum/.airflow/lib/python3.10/site-packages/airflow/providers/google/cloud/hooks/gcs.py", line 528, in _call_with_retry
    f()
  File "/Users/yueyaoz/.pyenv/versions/3.10.13/lib/python3.10/contextlib.py", line 79, in inner
    return func(*args, **kwds)
  File "/Users/yueyaoz/Downloads/IS3107-FinSum/.airflow/lib/python3.10/site-packages/google/cloud/storage/blob.py", line 3006, in upload_from_filename
    self._handle_filename_and_upload(
  File "/Users/yueyaoz/Downloads/IS3107-FinSum/.airflow/lib/python3.10/site-packages/google/cloud/storage/blob.py", line 2884, in _handle_filename_and_upload
    self._prep_and_do_upload(
  File "/Users/yueyaoz/Downloads/IS3107-FinSum/.airflow/lib/python3.10/site-packages/google/cloud/storage/blob.py", line 2718, in _prep_and_do_upload
    _raise_from_invalid_response(exc)
  File "/Users/yueyaoz/Downloads/IS3107-FinSum/.airflow/lib/python3.10/site-packages/google/cloud/storage/blob.py", line 4908, in _raise_from_invalid_response
    raise exceptions.from_http_status(response.status_code, message, response=response)
google.api_core.exceptions.Forbidden: 403 POST https://storage.googleapis.com/upload/storage/v1/b/my-data-is3107/o?uploadType=multipart: {
  "error": {
    "code": 403,
    "message": "is3107-project@is3107zyy.iam.gserviceaccount.com does not have storage.objects.create access to the Google Cloud Storage object. Permission 'storage.objects.create' denied on resource (or it may not exist).",
    "errors": [
      {
        "message": "is3107-project@is3107zyy.iam.gserviceaccount.com does not have storage.objects.create access to the Google Cloud Storage object. Permission 'storage.objects.create' denied on resource (or it may not exist).",
        "domain": "global",
        "reason": "forbidden"
      }
    ]
  }
}
: ('Request failed with status code', 403, 'Expected one of', <HTTPStatus.OK: 200>)
[2025-04-18T22:22:24.030+0800] {local_task_job_runner.py:266} INFO - Task exited with return code 1
[2025-04-18T22:22:24.043+0800] {taskinstance.py:3901} INFO - 0 downstream tasks scheduled from follow-on schedule check
[2025-04-18T22:22:24.045+0800] {local_task_job_runner.py:245} INFO - ::endgroup::
