[2025-03-17T20:01:05.573+0800] {local_task_job_runner.py:123} INFO - ::group::Pre task execution logs
[2025-03-17T20:01:05.579+0800] {taskinstance.py:2614} INFO - Dependencies all met for dep_context=non-requeueable deps ti=<TaskInstance: test_gcs_upload.upload_test_file manual__2025-03-17T12:01:01.823236+00:00 [queued]>
[2025-03-17T20:01:05.582+0800] {taskinstance.py:2614} INFO - Dependencies all met for dep_context=requeueable deps ti=<TaskInstance: test_gcs_upload.upload_test_file manual__2025-03-17T12:01:01.823236+00:00 [queued]>
[2025-03-17T20:01:05.582+0800] {taskinstance.py:2867} INFO - Starting attempt 1 of 1
[2025-03-17T20:01:05.587+0800] {taskinstance.py:2890} INFO - Executing <Task(LocalFilesystemToGCSOperator): upload_test_file> on 2025-03-17 12:01:01.823236+00:00
[2025-03-17T20:01:05.590+0800] {standard_task_runner.py:72} INFO - Started process 17790 to run task
[2025-03-17T20:01:05.594+0800] {standard_task_runner.py:104} INFO - Running: ['airflow', 'tasks', 'run', 'test_gcs_upload', 'upload_test_file', 'manual__2025-03-17T12:01:01.823236+00:00', '--job-id', '13', '--raw', '--subdir', 'DAGS_FOLDER/dag.py', '--cfg-path', '/var/folders/xg/h9xj0trn3dxds251bj2q6hf80000gn/T/tmphk3azwps']
[2025-03-17T20:01:05.595+0800] {standard_task_runner.py:105} INFO - Job 13: Subtask upload_test_file
[2025-03-17T20:01:05.621+0800] {task_command.py:467} INFO - Running <TaskInstance: test_gcs_upload.upload_test_file manual__2025-03-17T12:01:01.823236+00:00 [running]> on host ervins-air-2
[2025-03-17T20:01:05.649+0800] {taskinstance.py:3134} INFO - Exporting env vars: AIRFLOW_CTX_DAG_OWNER='airflow' AIRFLOW_CTX_DAG_ID='test_gcs_upload' AIRFLOW_CTX_TASK_ID='upload_test_file' AIRFLOW_CTX_EXECUTION_DATE='2025-03-17T12:01:01.823236+00:00' AIRFLOW_CTX_TRY_NUMBER='1' AIRFLOW_CTX_DAG_RUN_ID='manual__2025-03-17T12:01:01.823236+00:00'
[2025-03-17T20:01:05.650+0800] {logging_mixin.py:190} INFO - Task instance is in running state
[2025-03-17T20:01:05.650+0800] {logging_mixin.py:190} INFO -  Previous state of the Task instance: queued
[2025-03-17T20:01:05.651+0800] {logging_mixin.py:190} INFO - Current task name:upload_test_file state:running start_date:2025-03-17 12:01:05.579598+00:00
[2025-03-17T20:01:05.651+0800] {logging_mixin.py:190} INFO - Dag name:test_gcs_upload and current dag run status:running
[2025-03-17T20:01:05.651+0800] {taskinstance.py:732} INFO - ::endgroup::
[2025-03-17T20:01:05.654+0800] {connection.py:277} WARNING - Connection schemes (type: google_cloud_platform) shall not contain '_' according to RFC3986.
[2025-03-17T20:01:05.657+0800] {base.py:84} INFO - Retrieving connection 'google_cloud_default'
[2025-03-17T20:01:05.657+0800] {credentials_provider.py:409} INFO - Getting connection using `google.auth.default()` since no explicit credentials are provided.
[2025-03-17T20:01:08.660+0800] {_metadata.py:142} WARNING - Compute Engine Metadata server unavailable on attempt 1 of 3. Reason: timed out
[2025-03-17T20:01:12.763+0800] {_metadata.py:142} WARNING - Compute Engine Metadata server unavailable on attempt 2 of 3. Reason: timed out
[2025-03-17T20:01:14.857+0800] {_metadata.py:142} WARNING - Compute Engine Metadata server unavailable on attempt 3 of 3. Reason: [Errno 64] Host is down
[2025-03-17T20:01:14.859+0800] {_default.py:362} WARNING - Authentication failed using Compute Engine authentication due to unavailable metadata server.
[2025-03-17T20:01:14.860+0800] {taskinstance.py:3313} ERROR - Task failed with exception
Traceback (most recent call last):
  File "/Users/ervinyeoh/Desktop/unimods/is3107/project/.venv/lib/python3.11/site-packages/airflow/models/taskinstance.py", line 768, in _execute_task
    result = _execute_callable(context=context, **execute_callable_kwargs)
             ^^^^^^^^^^^^^^^^^^^^^^^^^^^^^^^^^^^^^^^^^^^^^^^^^^^^^^^^^^^^^
  File "/Users/ervinyeoh/Desktop/unimods/is3107/project/.venv/lib/python3.11/site-packages/airflow/models/taskinstance.py", line 734, in _execute_callable
    return ExecutionCallableRunner(
           ^^^^^^^^^^^^^^^^^^^^^^^^
  File "/Users/ervinyeoh/Desktop/unimods/is3107/project/.venv/lib/python3.11/site-packages/airflow/utils/operator_helpers.py", line 252, in run
    return self.func(*args, **kwargs)
           ^^^^^^^^^^^^^^^^^^^^^^^^^^
  File "/Users/ervinyeoh/Desktop/unimods/is3107/project/.venv/lib/python3.11/site-packages/airflow/models/baseoperator.py", line 424, in wrapper
    return func(self, *args, **kwargs)
           ^^^^^^^^^^^^^^^^^^^^^^^^^^^
  File "/Users/ervinyeoh/Desktop/unimods/is3107/project/.venv/lib/python3.11/site-packages/airflow/providers/google/cloud/transfers/local_to_gcs.py", line 115, in execute
    hook.upload(
  File "/Users/ervinyeoh/Desktop/unimods/is3107/project/.venv/lib/python3.11/site-packages/airflow/providers/google/cloud/hooks/gcs.py", line 544, in upload
    client = self.get_conn()
             ^^^^^^^^^^^^^^^
  File "/Users/ervinyeoh/Desktop/unimods/is3107/project/.venv/lib/python3.11/site-packages/airflow/providers/google/cloud/hooks/gcs.py", line 160, in get_conn
    credentials=self.get_credentials(), client_info=CLIENT_INFO, project=self.project_id
                ^^^^^^^^^^^^^^^^^^^^^^
  File "/Users/ervinyeoh/Desktop/unimods/is3107/project/.venv/lib/python3.11/site-packages/airflow/providers/google/common/hooks/base_google.py", line 357, in get_credentials
    credentials, _ = self.get_credentials_and_project_id()
                     ^^^^^^^^^^^^^^^^^^^^^^^^^^^^^^^^^^^^^
  File "/Users/ervinyeoh/Desktop/unimods/is3107/project/.venv/lib/python3.11/site-packages/airflow/providers/google/common/hooks/base_google.py", line 330, in get_credentials_and_project_id
    credentials, project_id = get_credentials_and_project_id(
                              ^^^^^^^^^^^^^^^^^^^^^^^^^^^^^^^
  File "/Users/ervinyeoh/Desktop/unimods/is3107/project/.venv/lib/python3.11/site-packages/airflow/providers/google/cloud/utils/credentials_provider.py", line 418, in get_credentials_and_project_id
    return _CredentialProvider(*args, **kwargs).get_credentials_and_project()
           ^^^^^^^^^^^^^^^^^^^^^^^^^^^^^^^^^^^^^^^^^^^^^^^^^^^^^^^^^^^^^^^^^^
  File "/Users/ervinyeoh/Desktop/unimods/is3107/project/.venv/lib/python3.11/site-packages/airflow/providers/google/cloud/utils/credentials_provider.py", line 276, in get_credentials_and_project
    credentials, project_id = self._get_credentials_using_adc()
                              ^^^^^^^^^^^^^^^^^^^^^^^^^^^^^^^^^
  File "/Users/ervinyeoh/Desktop/unimods/is3107/project/.venv/lib/python3.11/site-packages/airflow/providers/google/cloud/utils/credentials_provider.py", line 404, in _get_credentials_using_adc
    credentials, project_id = google.auth.default(scopes=self.scopes)
                              ^^^^^^^^^^^^^^^^^^^^^^^^^^^^^^^^^^^^^^^
  File "/Users/ervinyeoh/Desktop/unimods/is3107/project/.venv/lib/python3.11/site-packages/google/auth/_default.py", line 719, in default
    raise exceptions.DefaultCredentialsError(_CLOUD_SDK_MISSING_CREDENTIALS)
google.auth.exceptions.DefaultCredentialsError: Your default credentials were not found. To set up Application Default Credentials, see https://cloud.google.com/docs/authentication/external/set-up-adc for more information.
[2025-03-17T20:01:14.874+0800] {logging_mixin.py:190} INFO - Task instance in failure state
[2025-03-17T20:01:14.874+0800] {logging_mixin.py:190} INFO - Task start:2025-03-17 12:01:05.579598+00:00 end:2025-03-17 12:01:14.873564+00:00 duration:9.293966
[2025-03-17T20:01:14.875+0800] {logging_mixin.py:190} INFO - Task:<Task(LocalFilesystemToGCSOperator): upload_test_file> dag:<DAG: test_gcs_upload> dagrun:<DagRun test_gcs_upload @ 2025-03-17 12:01:01.823236+00:00: manual__2025-03-17T12:01:01.823236+00:00, state:running, queued_at: 2025-03-17 12:01:01.836894+00:00. externally triggered: True>
[2025-03-17T20:01:14.875+0800] {logging_mixin.py:190} INFO - Failure caused by Your default credentials were not found. To set up Application Default Credentials, see https://cloud.google.com/docs/authentication/external/set-up-adc for more information.
[2025-03-17T20:01:14.875+0800] {taskinstance.py:1226} INFO - Marking task as FAILED. dag_id=test_gcs_upload, task_id=upload_test_file, run_id=manual__2025-03-17T12:01:01.823236+00:00, execution_date=20250317T120101, start_date=20250317T120105, end_date=20250317T120114
[2025-03-17T20:01:14.894+0800] {taskinstance.py:341} INFO - ::group::Post task execution logs
[2025-03-17T20:01:14.894+0800] {standard_task_runner.py:124} ERROR - Failed to execute job 13 for task upload_test_file (Your default credentials were not found. To set up Application Default Credentials, see https://cloud.google.com/docs/authentication/external/set-up-adc for more information.; 17790)
Traceback (most recent call last):
  File "/Users/ervinyeoh/Desktop/unimods/is3107/project/.venv/lib/python3.11/site-packages/airflow/task/task_runner/standard_task_runner.py", line 117, in _start_by_fork
    ret = args.func(args, dag=self.dag)
          ^^^^^^^^^^^^^^^^^^^^^^^^^^^^^
  File "/Users/ervinyeoh/Desktop/unimods/is3107/project/.venv/lib/python3.11/site-packages/airflow/cli/cli_config.py", line 49, in command
    return func(*args, **kwargs)
           ^^^^^^^^^^^^^^^^^^^^^
  File "/Users/ervinyeoh/Desktop/unimods/is3107/project/.venv/lib/python3.11/site-packages/airflow/utils/cli.py", line 116, in wrapper
    return f(*args, **kwargs)
           ^^^^^^^^^^^^^^^^^^
  File "/Users/ervinyeoh/Desktop/unimods/is3107/project/.venv/lib/python3.11/site-packages/airflow/cli/commands/task_command.py", line 483, in task_run
    task_return_code = _run_task_by_selected_method(args, _dag, ti)
                       ^^^^^^^^^^^^^^^^^^^^^^^^^^^^^^^^^^^^^^^^^^^^
  File "/Users/ervinyeoh/Desktop/unimods/is3107/project/.venv/lib/python3.11/site-packages/airflow/cli/commands/task_command.py", line 256, in _run_task_by_selected_method
    return _run_raw_task(args, ti)
           ^^^^^^^^^^^^^^^^^^^^^^^
  File "/Users/ervinyeoh/Desktop/unimods/is3107/project/.venv/lib/python3.11/site-packages/airflow/cli/commands/task_command.py", line 341, in _run_raw_task
    return ti._run_raw_task(
           ^^^^^^^^^^^^^^^^^
  File "/Users/ervinyeoh/Desktop/unimods/is3107/project/.venv/lib/python3.11/site-packages/airflow/utils/session.py", line 97, in wrapper
    return func(*args, session=session, **kwargs)
           ^^^^^^^^^^^^^^^^^^^^^^^^^^^^^^^^^^^^^^
  File "/Users/ervinyeoh/Desktop/unimods/is3107/project/.venv/lib/python3.11/site-packages/airflow/models/taskinstance.py", line 3006, in _run_raw_task
    return _run_raw_task(
           ^^^^^^^^^^^^^^
  File "/Users/ervinyeoh/Desktop/unimods/is3107/project/.venv/lib/python3.11/site-packages/airflow/models/taskinstance.py", line 274, in _run_raw_task
    TaskInstance._execute_task_with_callbacks(
  File "/Users/ervinyeoh/Desktop/unimods/is3107/project/.venv/lib/python3.11/site-packages/airflow/models/taskinstance.py", line 3161, in _execute_task_with_callbacks
    result = self._execute_task(context, task_orig)
             ^^^^^^^^^^^^^^^^^^^^^^^^^^^^^^^^^^^^^^
  File "/Users/ervinyeoh/Desktop/unimods/is3107/project/.venv/lib/python3.11/site-packages/airflow/models/taskinstance.py", line 3185, in _execute_task
    return _execute_task(self, context, task_orig)
           ^^^^^^^^^^^^^^^^^^^^^^^^^^^^^^^^^^^^^^^
  File "/Users/ervinyeoh/Desktop/unimods/is3107/project/.venv/lib/python3.11/site-packages/airflow/models/taskinstance.py", line 768, in _execute_task
    result = _execute_callable(context=context, **execute_callable_kwargs)
             ^^^^^^^^^^^^^^^^^^^^^^^^^^^^^^^^^^^^^^^^^^^^^^^^^^^^^^^^^^^^^
  File "/Users/ervinyeoh/Desktop/unimods/is3107/project/.venv/lib/python3.11/site-packages/airflow/models/taskinstance.py", line 734, in _execute_callable
    return ExecutionCallableRunner(
           ^^^^^^^^^^^^^^^^^^^^^^^^
  File "/Users/ervinyeoh/Desktop/unimods/is3107/project/.venv/lib/python3.11/site-packages/airflow/utils/operator_helpers.py", line 252, in run
    return self.func(*args, **kwargs)
           ^^^^^^^^^^^^^^^^^^^^^^^^^^
  File "/Users/ervinyeoh/Desktop/unimods/is3107/project/.venv/lib/python3.11/site-packages/airflow/models/baseoperator.py", line 424, in wrapper
    return func(self, *args, **kwargs)
           ^^^^^^^^^^^^^^^^^^^^^^^^^^^
  File "/Users/ervinyeoh/Desktop/unimods/is3107/project/.venv/lib/python3.11/site-packages/airflow/providers/google/cloud/transfers/local_to_gcs.py", line 115, in execute
    hook.upload(
  File "/Users/ervinyeoh/Desktop/unimods/is3107/project/.venv/lib/python3.11/site-packages/airflow/providers/google/cloud/hooks/gcs.py", line 544, in upload
    client = self.get_conn()
             ^^^^^^^^^^^^^^^
  File "/Users/ervinyeoh/Desktop/unimods/is3107/project/.venv/lib/python3.11/site-packages/airflow/providers/google/cloud/hooks/gcs.py", line 160, in get_conn
    credentials=self.get_credentials(), client_info=CLIENT_INFO, project=self.project_id
                ^^^^^^^^^^^^^^^^^^^^^^
  File "/Users/ervinyeoh/Desktop/unimods/is3107/project/.venv/lib/python3.11/site-packages/airflow/providers/google/common/hooks/base_google.py", line 357, in get_credentials
    credentials, _ = self.get_credentials_and_project_id()
                     ^^^^^^^^^^^^^^^^^^^^^^^^^^^^^^^^^^^^^
  File "/Users/ervinyeoh/Desktop/unimods/is3107/project/.venv/lib/python3.11/site-packages/airflow/providers/google/common/hooks/base_google.py", line 330, in get_credentials_and_project_id
    credentials, project_id = get_credentials_and_project_id(
                              ^^^^^^^^^^^^^^^^^^^^^^^^^^^^^^^
  File "/Users/ervinyeoh/Desktop/unimods/is3107/project/.venv/lib/python3.11/site-packages/airflow/providers/google/cloud/utils/credentials_provider.py", line 418, in get_credentials_and_project_id
    return _CredentialProvider(*args, **kwargs).get_credentials_and_project()
           ^^^^^^^^^^^^^^^^^^^^^^^^^^^^^^^^^^^^^^^^^^^^^^^^^^^^^^^^^^^^^^^^^^
  File "/Users/ervinyeoh/Desktop/unimods/is3107/project/.venv/lib/python3.11/site-packages/airflow/providers/google/cloud/utils/credentials_provider.py", line 276, in get_credentials_and_project
    credentials, project_id = self._get_credentials_using_adc()
                              ^^^^^^^^^^^^^^^^^^^^^^^^^^^^^^^^^
  File "/Users/ervinyeoh/Desktop/unimods/is3107/project/.venv/lib/python3.11/site-packages/airflow/providers/google/cloud/utils/credentials_provider.py", line 404, in _get_credentials_using_adc
    credentials, project_id = google.auth.default(scopes=self.scopes)
                              ^^^^^^^^^^^^^^^^^^^^^^^^^^^^^^^^^^^^^^^
  File "/Users/ervinyeoh/Desktop/unimods/is3107/project/.venv/lib/python3.11/site-packages/google/auth/_default.py", line 719, in default
    raise exceptions.DefaultCredentialsError(_CLOUD_SDK_MISSING_CREDENTIALS)
google.auth.exceptions.DefaultCredentialsError: Your default credentials were not found. To set up Application Default Credentials, see https://cloud.google.com/docs/authentication/external/set-up-adc for more information.
[2025-03-17T20:01:14.915+0800] {local_task_job_runner.py:266} INFO - Task exited with return code 1
[2025-03-17T20:01:14.925+0800] {taskinstance.py:3901} INFO - 0 downstream tasks scheduled from follow-on schedule check
[2025-03-17T20:01:14.925+0800] {local_task_job_runner.py:245} INFO - ::endgroup::
