[2025-04-22T03:29:10.567+0800] {local_task_job_runner.py:123} INFO - ::group::Pre task execution logs
[2025-04-22T03:29:10.573+0800] {taskinstance.py:2614} INFO - Dependencies all met for dep_context=non-requeueable deps ti=<TaskInstance: reddit_yf_scraper.run_yf scheduled__2025-04-20T19:00:00+00:00 [queued]>
[2025-04-22T03:29:10.575+0800] {taskinstance.py:2614} INFO - Dependencies all met for dep_context=requeueable deps ti=<TaskInstance: reddit_yf_scraper.run_yf scheduled__2025-04-20T19:00:00+00:00 [queued]>
[2025-04-22T03:29:10.576+0800] {taskinstance.py:2867} INFO - Starting attempt 1 of 2
[2025-04-22T03:29:10.580+0800] {taskinstance.py:2890} INFO - Executing <Task(_PythonDecoratedOperator): run_yf> on 2025-04-20 19:00:00+00:00
[2025-04-22T03:29:10.584+0800] {standard_task_runner.py:72} INFO - Started process 12549 to run task
[2025-04-22T03:29:10.587+0800] {standard_task_runner.py:104} INFO - Running: ['airflow', 'tasks', 'run', 'reddit_yf_scraper', 'run_yf', 'scheduled__2025-04-20T19:00:00+00:00', '--job-id', '861', '--raw', '--subdir', 'DAGS_FOLDER/dag.py', '--cfg-path', '/var/folders/2f/rw5w89ss6nl38qvq2cxrh29w0000gn/T/tmprs32mi0s']
[2025-04-22T03:29:10.588+0800] {standard_task_runner.py:105} INFO - Job 861: Subtask run_yf
[2025-04-22T03:29:10.608+0800] {task_command.py:467} INFO - Running <TaskInstance: reddit_yf_scraper.run_yf scheduled__2025-04-20T19:00:00+00:00 [running]> on host yueyaos-macbook-pro.local
[2025-04-22T03:29:10.633+0800] {taskinstance.py:3134} INFO - Exporting env vars: AIRFLOW_CTX_DAG_OWNER='airflow' AIRFLOW_CTX_DAG_ID='reddit_yf_scraper' AIRFLOW_CTX_TASK_ID='run_yf' AIRFLOW_CTX_EXECUTION_DATE='2025-04-20T19:00:00+00:00' AIRFLOW_CTX_TRY_NUMBER='1' AIRFLOW_CTX_DAG_RUN_ID='scheduled__2025-04-20T19:00:00+00:00'
[2025-04-22T03:29:10.633+0800] {logging_mixin.py:190} INFO - Task instance is in running state
[2025-04-22T03:29:10.634+0800] {logging_mixin.py:190} INFO -  Previous state of the Task instance: queued
[2025-04-22T03:29:10.634+0800] {logging_mixin.py:190} INFO - Current task name:run_yf state:running start_date:2025-04-21 19:29:10.573347+00:00
[2025-04-22T03:29:10.634+0800] {logging_mixin.py:190} INFO - Dag name:reddit_yf_scraper and current dag run status:running
[2025-04-22T03:29:10.634+0800] {taskinstance.py:732} INFO - ::endgroup::
[2025-04-22T03:29:10.635+0800] {logging_mixin.py:190} INFO - üîç Fetching news for CTVA (1/100)...
[2025-04-22T03:46:12.313+0800] {job.py:229} INFO - Heartbeat recovered after 1021.77 seconds
[2025-04-22T04:02:25.933+0800] {job.py:229} INFO - Heartbeat recovered after 973.62 seconds
[2025-04-22T04:17:36.082+0800] {logging_mixin.py:190} INFO - üîç Fetching news for CF (2/100)...
[2025-04-22T04:17:37.534+0800] {job.py:229} INFO - Heartbeat recovered after 911.60 seconds
[2025-04-22T04:35:37.177+0800] {job.py:229} INFO - Heartbeat recovered after 1079.65 seconds
[2025-04-22T04:52:05.840+0800] {job.py:229} INFO - Heartbeat recovered after 988.67 seconds
[2025-04-22T04:52:07.620+0800] {logging_mixin.py:190} INFO - üîç Fetching news for MOS (3/100)...
[2025-04-22T05:07:38.396+0800] {job.py:229} INFO - Heartbeat recovered after 932.56 seconds
[2025-04-22T05:23:48.838+0800] {logging_mixin.py:190} INFO - üîç Fetching news for FMC (4/100)...
[2025-04-22T05:23:48.907+0800] {job.py:229} INFO - Heartbeat recovered after 965.47 seconds
[2025-04-22T05:41:31.568+0800] {job.py:229} INFO - Heartbeat recovered after 1062.66 seconds
[2025-04-22T05:41:39.212+0800] {logging_mixin.py:190} INFO - üîç Fetching news for VMC (5/100)...
[2025-04-22T05:41:51.914+0800] {logging_mixin.py:190} INFO - üîç Fetching news for MLM (6/100)...
[2025-04-22T05:58:46.477+0800] {job.py:229} INFO - Heartbeat recovered after 1009.74 seconds
[2025-04-22T05:58:49.539+0800] {logging_mixin.py:190} INFO - üîç Fetching news for DOW (7/100)...
[2025-04-22T06:14:30.925+0800] {job.py:229} INFO - Heartbeat recovered after 939.42 seconds
[2025-04-22T06:29:32.329+0800] {job.py:229} INFO - Heartbeat recovered after 901.41 seconds
[2025-04-22T06:29:32.986+0800] {logging_mixin.py:190} INFO - üîç Fetching news for CE (8/100)...
[2025-04-22T06:45:28.748+0800] {job.py:229} INFO - Heartbeat recovered after 956.42 seconds
[2025-04-22T07:04:28.939+0800] {job.py:229} INFO - Heartbeat recovered after 963.95 seconds
[2025-04-22T07:08:39.557+0800] {job.py:229} INFO - Heartbeat recovered after 250.62 seconds
[2025-04-22T07:25:37.459+0800] {job.py:229} INFO - Heartbeat recovered after 1012.85 seconds
[2025-04-22T07:25:39.920+0800] {taskinstance.py:3313} ERROR - Task failed with exception
Traceback (most recent call last):
  File "/Users/yueyaoz/Downloads/IS3107-FinSum/.airflow/lib/python3.10/site-packages/urllib3/connectionpool.py", line 787, in urlopen
    response = self._make_request(
  File "/Users/yueyaoz/Downloads/IS3107-FinSum/.airflow/lib/python3.10/site-packages/urllib3/connectionpool.py", line 534, in _make_request
    response = conn.getresponse()
  File "/Users/yueyaoz/Downloads/IS3107-FinSum/.airflow/lib/python3.10/site-packages/urllib3/connection.py", line 516, in getresponse
    httplib_response = super().getresponse()
  File "/Users/yueyaoz/.pyenv/versions/3.10.13/lib/python3.10/http/client.py", line 1375, in getresponse
    response.begin()
  File "/Users/yueyaoz/.pyenv/versions/3.10.13/lib/python3.10/http/client.py", line 318, in begin
    version, status, reason = self._read_status()
  File "/Users/yueyaoz/.pyenv/versions/3.10.13/lib/python3.10/http/client.py", line 287, in _read_status
    raise RemoteDisconnected("Remote end closed connection without"
http.client.RemoteDisconnected: Remote end closed connection without response

During handling of the above exception, another exception occurred:

Traceback (most recent call last):
  File "/Users/yueyaoz/Downloads/IS3107-FinSum/.airflow/lib/python3.10/site-packages/requests/adapters.py", line 667, in send
    resp = conn.urlopen(
  File "/Users/yueyaoz/Downloads/IS3107-FinSum/.airflow/lib/python3.10/site-packages/urllib3/connectionpool.py", line 841, in urlopen
    retries = retries.increment(
  File "/Users/yueyaoz/Downloads/IS3107-FinSum/.airflow/lib/python3.10/site-packages/urllib3/util/retry.py", line 474, in increment
    raise reraise(type(error), error, _stacktrace)
  File "/Users/yueyaoz/Downloads/IS3107-FinSum/.airflow/lib/python3.10/site-packages/urllib3/util/util.py", line 38, in reraise
    raise value.with_traceback(tb)
  File "/Users/yueyaoz/Downloads/IS3107-FinSum/.airflow/lib/python3.10/site-packages/urllib3/connectionpool.py", line 787, in urlopen
    response = self._make_request(
  File "/Users/yueyaoz/Downloads/IS3107-FinSum/.airflow/lib/python3.10/site-packages/urllib3/connectionpool.py", line 534, in _make_request
    response = conn.getresponse()
  File "/Users/yueyaoz/Downloads/IS3107-FinSum/.airflow/lib/python3.10/site-packages/urllib3/connection.py", line 516, in getresponse
    httplib_response = super().getresponse()
  File "/Users/yueyaoz/.pyenv/versions/3.10.13/lib/python3.10/http/client.py", line 1375, in getresponse
    response.begin()
  File "/Users/yueyaoz/.pyenv/versions/3.10.13/lib/python3.10/http/client.py", line 318, in begin
    version, status, reason = self._read_status()
  File "/Users/yueyaoz/.pyenv/versions/3.10.13/lib/python3.10/http/client.py", line 287, in _read_status
    raise RemoteDisconnected("Remote end closed connection without"
urllib3.exceptions.ProtocolError: ('Connection aborted.', RemoteDisconnected('Remote end closed connection without response'))

During handling of the above exception, another exception occurred:

Traceback (most recent call last):
  File "/Users/yueyaoz/Downloads/IS3107-FinSum/.airflow/lib/python3.10/site-packages/airflow/models/taskinstance.py", line 768, in _execute_task
    result = _execute_callable(context=context, **execute_callable_kwargs)
  File "/Users/yueyaoz/Downloads/IS3107-FinSum/.airflow/lib/python3.10/site-packages/airflow/models/taskinstance.py", line 734, in _execute_callable
    return ExecutionCallableRunner(
  File "/Users/yueyaoz/Downloads/IS3107-FinSum/.airflow/lib/python3.10/site-packages/airflow/utils/operator_helpers.py", line 252, in run
    return self.func(*args, **kwargs)
  File "/Users/yueyaoz/Downloads/IS3107-FinSum/.airflow/lib/python3.10/site-packages/airflow/models/baseoperator.py", line 424, in wrapper
    return func(self, *args, **kwargs)
  File "/Users/yueyaoz/Downloads/IS3107-FinSum/.airflow/lib/python3.10/site-packages/airflow/decorators/base.py", line 266, in execute
    return_value = super().execute(context)
  File "/Users/yueyaoz/Downloads/IS3107-FinSum/.airflow/lib/python3.10/site-packages/airflow/models/baseoperator.py", line 424, in wrapper
    return func(self, *args, **kwargs)
  File "/Users/yueyaoz/Downloads/IS3107-FinSum/.airflow/lib/python3.10/site-packages/airflow/operators/python.py", line 238, in execute
    return_value = self.execute_callable()
  File "/Users/yueyaoz/Downloads/IS3107-FinSum/.airflow/lib/python3.10/site-packages/airflow/operators/python.py", line 256, in execute_callable
    return runner.run(*self.op_args, **self.op_kwargs)
  File "/Users/yueyaoz/Downloads/IS3107-FinSum/.airflow/lib/python3.10/site-packages/airflow/utils/operator_helpers.py", line 252, in run
    return self.func(*args, **kwargs)
  File "/Users/yueyaoz/Downloads/IS3107-FinSum/airflow/dags/dag.py", line 115, in run_yf
    run_yf_scraper(tickers)
  File "/Users/yueyaoz/Downloads/IS3107-FinSum/airflow/dags/yf_scraper.py", line 33, in run_yf_scraper
    response = requests.get(YF_API_URL, params=params)
  File "/Users/yueyaoz/Downloads/IS3107-FinSum/.airflow/lib/python3.10/site-packages/requests/api.py", line 73, in get
    return request("get", url, params=params, **kwargs)
  File "/Users/yueyaoz/Downloads/IS3107-FinSum/.airflow/lib/python3.10/site-packages/requests/api.py", line 59, in request
    return session.request(method=method, url=url, **kwargs)
  File "/Users/yueyaoz/Downloads/IS3107-FinSum/.airflow/lib/python3.10/site-packages/requests/sessions.py", line 589, in request
    resp = self.send(prep, **send_kwargs)
  File "/Users/yueyaoz/Downloads/IS3107-FinSum/.airflow/lib/python3.10/site-packages/requests/sessions.py", line 703, in send
    r = adapter.send(request, **kwargs)
  File "/Users/yueyaoz/Downloads/IS3107-FinSum/.airflow/lib/python3.10/site-packages/requests/adapters.py", line 682, in send
    raise ConnectionError(err, request=request)
requests.exceptions.ConnectionError: ('Connection aborted.', RemoteDisconnected('Remote end closed connection without response'))
[2025-04-22T07:25:39.946+0800] {logging_mixin.py:190} INFO - Task instance in failure state
[2025-04-22T07:25:39.947+0800] {logging_mixin.py:190} INFO - Task start:2025-04-21 19:29:10.573347+00:00 end:2025-04-21 23:25:39.946044+00:00 duration:14189.372697
[2025-04-22T07:25:39.947+0800] {logging_mixin.py:190} INFO - Task:<Task(_PythonDecoratedOperator): run_yf> dag:<DAG: reddit_yf_scraper> dagrun:<DagRun reddit_yf_scraper @ 2025-04-20 19:00:00+00:00: scheduled__2025-04-20T19:00:00+00:00, state:running, queued_at: 2025-04-21 19:13:34.851036+00:00. externally triggered: False>
[2025-04-22T07:25:39.948+0800] {logging_mixin.py:190} INFO - Failure caused by ('Connection aborted.', RemoteDisconnected('Remote end closed connection without response'))
[2025-04-22T07:25:39.948+0800] {taskinstance.py:1226} INFO - Marking task as UP_FOR_RETRY. dag_id=reddit_yf_scraper, task_id=run_yf, run_id=scheduled__2025-04-20T19:00:00+00:00, execution_date=20250420T190000, start_date=20250421T192910, end_date=20250421T232539
[2025-04-22T07:25:39.963+0800] {taskinstance.py:341} INFO - ::group::Post task execution logs
[2025-04-22T07:25:39.963+0800] {standard_task_runner.py:124} ERROR - Failed to execute job 861 for task run_yf (('Connection aborted.', RemoteDisconnected('Remote end closed connection without response')); 12549)
Traceback (most recent call last):
  File "/Users/yueyaoz/Downloads/IS3107-FinSum/.airflow/lib/python3.10/site-packages/urllib3/connectionpool.py", line 787, in urlopen
    response = self._make_request(
  File "/Users/yueyaoz/Downloads/IS3107-FinSum/.airflow/lib/python3.10/site-packages/urllib3/connectionpool.py", line 534, in _make_request
    response = conn.getresponse()
  File "/Users/yueyaoz/Downloads/IS3107-FinSum/.airflow/lib/python3.10/site-packages/urllib3/connection.py", line 516, in getresponse
    httplib_response = super().getresponse()
  File "/Users/yueyaoz/.pyenv/versions/3.10.13/lib/python3.10/http/client.py", line 1375, in getresponse
    response.begin()
  File "/Users/yueyaoz/.pyenv/versions/3.10.13/lib/python3.10/http/client.py", line 318, in begin
    version, status, reason = self._read_status()
  File "/Users/yueyaoz/.pyenv/versions/3.10.13/lib/python3.10/http/client.py", line 287, in _read_status
    raise RemoteDisconnected("Remote end closed connection without"
http.client.RemoteDisconnected: Remote end closed connection without response

During handling of the above exception, another exception occurred:

Traceback (most recent call last):
  File "/Users/yueyaoz/Downloads/IS3107-FinSum/.airflow/lib/python3.10/site-packages/requests/adapters.py", line 667, in send
    resp = conn.urlopen(
  File "/Users/yueyaoz/Downloads/IS3107-FinSum/.airflow/lib/python3.10/site-packages/urllib3/connectionpool.py", line 841, in urlopen
    retries = retries.increment(
  File "/Users/yueyaoz/Downloads/IS3107-FinSum/.airflow/lib/python3.10/site-packages/urllib3/util/retry.py", line 474, in increment
    raise reraise(type(error), error, _stacktrace)
  File "/Users/yueyaoz/Downloads/IS3107-FinSum/.airflow/lib/python3.10/site-packages/urllib3/util/util.py", line 38, in reraise
    raise value.with_traceback(tb)
  File "/Users/yueyaoz/Downloads/IS3107-FinSum/.airflow/lib/python3.10/site-packages/urllib3/connectionpool.py", line 787, in urlopen
    response = self._make_request(
  File "/Users/yueyaoz/Downloads/IS3107-FinSum/.airflow/lib/python3.10/site-packages/urllib3/connectionpool.py", line 534, in _make_request
    response = conn.getresponse()
  File "/Users/yueyaoz/Downloads/IS3107-FinSum/.airflow/lib/python3.10/site-packages/urllib3/connection.py", line 516, in getresponse
    httplib_response = super().getresponse()
  File "/Users/yueyaoz/.pyenv/versions/3.10.13/lib/python3.10/http/client.py", line 1375, in getresponse
    response.begin()
  File "/Users/yueyaoz/.pyenv/versions/3.10.13/lib/python3.10/http/client.py", line 318, in begin
    version, status, reason = self._read_status()
  File "/Users/yueyaoz/.pyenv/versions/3.10.13/lib/python3.10/http/client.py", line 287, in _read_status
    raise RemoteDisconnected("Remote end closed connection without"
urllib3.exceptions.ProtocolError: ('Connection aborted.', RemoteDisconnected('Remote end closed connection without response'))

During handling of the above exception, another exception occurred:

Traceback (most recent call last):
  File "/Users/yueyaoz/Downloads/IS3107-FinSum/.airflow/lib/python3.10/site-packages/airflow/task/task_runner/standard_task_runner.py", line 117, in _start_by_fork
    ret = args.func(args, dag=self.dag)
  File "/Users/yueyaoz/Downloads/IS3107-FinSum/.airflow/lib/python3.10/site-packages/airflow/cli/cli_config.py", line 49, in command
    return func(*args, **kwargs)
  File "/Users/yueyaoz/Downloads/IS3107-FinSum/.airflow/lib/python3.10/site-packages/airflow/utils/cli.py", line 116, in wrapper
    return f(*args, **kwargs)
  File "/Users/yueyaoz/Downloads/IS3107-FinSum/.airflow/lib/python3.10/site-packages/airflow/cli/commands/task_command.py", line 483, in task_run
    task_return_code = _run_task_by_selected_method(args, _dag, ti)
  File "/Users/yueyaoz/Downloads/IS3107-FinSum/.airflow/lib/python3.10/site-packages/airflow/cli/commands/task_command.py", line 256, in _run_task_by_selected_method
    return _run_raw_task(args, ti)
  File "/Users/yueyaoz/Downloads/IS3107-FinSum/.airflow/lib/python3.10/site-packages/airflow/cli/commands/task_command.py", line 341, in _run_raw_task
    return ti._run_raw_task(
  File "/Users/yueyaoz/Downloads/IS3107-FinSum/.airflow/lib/python3.10/site-packages/airflow/utils/session.py", line 97, in wrapper
    return func(*args, session=session, **kwargs)
  File "/Users/yueyaoz/Downloads/IS3107-FinSum/.airflow/lib/python3.10/site-packages/airflow/models/taskinstance.py", line 3006, in _run_raw_task
    return _run_raw_task(
  File "/Users/yueyaoz/Downloads/IS3107-FinSum/.airflow/lib/python3.10/site-packages/airflow/models/taskinstance.py", line 274, in _run_raw_task
    TaskInstance._execute_task_with_callbacks(
  File "/Users/yueyaoz/Downloads/IS3107-FinSum/.airflow/lib/python3.10/site-packages/airflow/models/taskinstance.py", line 3161, in _execute_task_with_callbacks
    result = self._execute_task(context, task_orig)
  File "/Users/yueyaoz/Downloads/IS3107-FinSum/.airflow/lib/python3.10/site-packages/airflow/models/taskinstance.py", line 3185, in _execute_task
    return _execute_task(self, context, task_orig)
  File "/Users/yueyaoz/Downloads/IS3107-FinSum/.airflow/lib/python3.10/site-packages/airflow/models/taskinstance.py", line 768, in _execute_task
    result = _execute_callable(context=context, **execute_callable_kwargs)
  File "/Users/yueyaoz/Downloads/IS3107-FinSum/.airflow/lib/python3.10/site-packages/airflow/models/taskinstance.py", line 734, in _execute_callable
    return ExecutionCallableRunner(
  File "/Users/yueyaoz/Downloads/IS3107-FinSum/.airflow/lib/python3.10/site-packages/airflow/utils/operator_helpers.py", line 252, in run
    return self.func(*args, **kwargs)
  File "/Users/yueyaoz/Downloads/IS3107-FinSum/.airflow/lib/python3.10/site-packages/airflow/models/baseoperator.py", line 424, in wrapper
    return func(self, *args, **kwargs)
  File "/Users/yueyaoz/Downloads/IS3107-FinSum/.airflow/lib/python3.10/site-packages/airflow/decorators/base.py", line 266, in execute
    return_value = super().execute(context)
  File "/Users/yueyaoz/Downloads/IS3107-FinSum/.airflow/lib/python3.10/site-packages/airflow/models/baseoperator.py", line 424, in wrapper
    return func(self, *args, **kwargs)
  File "/Users/yueyaoz/Downloads/IS3107-FinSum/.airflow/lib/python3.10/site-packages/airflow/operators/python.py", line 238, in execute
    return_value = self.execute_callable()
  File "/Users/yueyaoz/Downloads/IS3107-FinSum/.airflow/lib/python3.10/site-packages/airflow/operators/python.py", line 256, in execute_callable
    return runner.run(*self.op_args, **self.op_kwargs)
  File "/Users/yueyaoz/Downloads/IS3107-FinSum/.airflow/lib/python3.10/site-packages/airflow/utils/operator_helpers.py", line 252, in run
    return self.func(*args, **kwargs)
  File "/Users/yueyaoz/Downloads/IS3107-FinSum/airflow/dags/dag.py", line 115, in run_yf
    run_yf_scraper(tickers)
  File "/Users/yueyaoz/Downloads/IS3107-FinSum/airflow/dags/yf_scraper.py", line 33, in run_yf_scraper
    response = requests.get(YF_API_URL, params=params)
  File "/Users/yueyaoz/Downloads/IS3107-FinSum/.airflow/lib/python3.10/site-packages/requests/api.py", line 73, in get
    return request("get", url, params=params, **kwargs)
  File "/Users/yueyaoz/Downloads/IS3107-FinSum/.airflow/lib/python3.10/site-packages/requests/api.py", line 59, in request
    return session.request(method=method, url=url, **kwargs)
  File "/Users/yueyaoz/Downloads/IS3107-FinSum/.airflow/lib/python3.10/site-packages/requests/sessions.py", line 589, in request
    resp = self.send(prep, **send_kwargs)
  File "/Users/yueyaoz/Downloads/IS3107-FinSum/.airflow/lib/python3.10/site-packages/requests/sessions.py", line 703, in send
    r = adapter.send(request, **kwargs)
  File "/Users/yueyaoz/Downloads/IS3107-FinSum/.airflow/lib/python3.10/site-packages/requests/adapters.py", line 682, in send
    raise ConnectionError(err, request=request)
requests.exceptions.ConnectionError: ('Connection aborted.', RemoteDisconnected('Remote end closed connection without response'))
[2025-04-22T07:25:39.998+0800] {local_task_job_runner.py:266} INFO - Task exited with return code 1
[2025-04-22T07:25:40.011+0800] {taskinstance.py:3901} INFO - 0 downstream tasks scheduled from follow-on schedule check
[2025-04-22T07:25:40.011+0800] {local_task_job_runner.py:245} INFO - ::endgroup::
