[2025-03-23T00:25:43.508+0800] {local_task_job_runner.py:123} INFO - ::group::Pre task execution logs
[2025-03-23T00:25:43.517+0800] {taskinstance.py:2614} INFO - Dependencies all met for dep_context=non-requeueable deps ti=<TaskInstance: reddit_yf_scraper.run_yf scheduled__2025-03-21T16:00:00+00:00 [queued]>
[2025-03-23T00:25:43.520+0800] {taskinstance.py:2614} INFO - Dependencies all met for dep_context=requeueable deps ti=<TaskInstance: reddit_yf_scraper.run_yf scheduled__2025-03-21T16:00:00+00:00 [queued]>
[2025-03-23T00:25:43.520+0800] {taskinstance.py:2867} INFO - Starting attempt 1 of 2
[2025-03-23T00:25:43.526+0800] {taskinstance.py:2890} INFO - Executing <Task(_PythonDecoratedOperator): run_yf> on 2025-03-21 16:00:00+00:00
[2025-03-23T00:25:43.528+0800] {standard_task_runner.py:72} INFO - Started process 95325 to run task
[2025-03-23T00:25:43.532+0800] {standard_task_runner.py:104} INFO - Running: ['airflow', 'tasks', 'run', 'reddit_yf_scraper', 'run_yf', 'scheduled__2025-03-21T16:00:00+00:00', '--job-id', '134', '--raw', '--subdir', 'DAGS_FOLDER/dag.py', '--cfg-path', '/var/folders/xg/h9xj0trn3dxds251bj2q6hf80000gn/T/tmpoy6kwl_j']
[2025-03-23T00:25:43.533+0800] {standard_task_runner.py:105} INFO - Job 134: Subtask run_yf
[2025-03-23T00:25:43.566+0800] {task_command.py:467} INFO - Running <TaskInstance: reddit_yf_scraper.run_yf scheduled__2025-03-21T16:00:00+00:00 [running]> on host ervins-air-2
[2025-03-23T00:25:43.610+0800] {taskinstance.py:3134} INFO - Exporting env vars: AIRFLOW_CTX_DAG_OWNER='airflow' AIRFLOW_CTX_DAG_ID='reddit_yf_scraper' AIRFLOW_CTX_TASK_ID='run_yf' AIRFLOW_CTX_EXECUTION_DATE='2025-03-21T16:00:00+00:00' AIRFLOW_CTX_TRY_NUMBER='1' AIRFLOW_CTX_DAG_RUN_ID='scheduled__2025-03-21T16:00:00+00:00'
[2025-03-23T00:25:43.611+0800] {logging_mixin.py:190} INFO - Task instance is in running state
[2025-03-23T00:25:43.611+0800] {logging_mixin.py:190} INFO -  Previous state of the Task instance: queued
[2025-03-23T00:25:43.611+0800] {logging_mixin.py:190} INFO - Current task name:run_yf state:running start_date:2025-03-22 16:25:43.517636+00:00
[2025-03-23T00:25:43.612+0800] {logging_mixin.py:190} INFO - Dag name:reddit_yf_scraper and current dag run status:running
[2025-03-23T00:25:43.612+0800] {taskinstance.py:732} INFO - ::endgroup::
[2025-03-23T00:25:43.612+0800] {logging_mixin.py:190} INFO - üîç Fetching news for AAPL (1/502)...
[2025-03-23T00:25:44.390+0800] {logging_mixin.py:190} INFO - ‚úÖ Saved 1 articles for AAPL
[2025-03-23T00:42:07.678+0800] {job.py:229} INFO - Heartbeat recovered after 979.08 seconds
[2025-03-23T00:59:43.468+0800] {logging_mixin.py:190} INFO - üîç Fetching news for NVDA (2/502)...
[2025-03-23T00:59:44.367+0800] {logging_mixin.py:190} INFO - ‚úÖ Saved 6 articles for NVDA
[2025-03-23T00:59:45.776+0800] {job.py:229} INFO - Heartbeat recovered after 1058.10 seconds
[2025-03-23T01:16:06.822+0800] {job.py:229} INFO - Heartbeat recovered after 981.05 seconds
[2025-03-23T01:16:12.348+0800] {logging_mixin.py:190} INFO - üîç Fetching news for MSFT (3/502)...
[2025-03-23T01:31:48.622+0800] {taskinstance.py:3313} ERROR - Task failed with exception
Traceback (most recent call last):
  File "/Users/ervinyeoh/Desktop/unimods/is3107/project/.venv/lib/python3.11/site-packages/urllib3/connectionpool.py", line 787, in urlopen
    response = self._make_request(
               ^^^^^^^^^^^^^^^^^^^
  File "/Users/ervinyeoh/Desktop/unimods/is3107/project/.venv/lib/python3.11/site-packages/urllib3/connectionpool.py", line 488, in _make_request
    raise new_e
  File "/Users/ervinyeoh/Desktop/unimods/is3107/project/.venv/lib/python3.11/site-packages/urllib3/connectionpool.py", line 464, in _make_request
    self._validate_conn(conn)
  File "/Users/ervinyeoh/Desktop/unimods/is3107/project/.venv/lib/python3.11/site-packages/urllib3/connectionpool.py", line 1093, in _validate_conn
    conn.connect()
  File "/Users/ervinyeoh/Desktop/unimods/is3107/project/.venv/lib/python3.11/site-packages/urllib3/connection.py", line 741, in connect
    sock_and_verified = _ssl_wrap_socket_and_match_hostname(
                        ^^^^^^^^^^^^^^^^^^^^^^^^^^^^^^^^^^^^
  File "/Users/ervinyeoh/Desktop/unimods/is3107/project/.venv/lib/python3.11/site-packages/urllib3/connection.py", line 920, in _ssl_wrap_socket_and_match_hostname
    ssl_sock = ssl_wrap_socket(
               ^^^^^^^^^^^^^^^^
  File "/Users/ervinyeoh/Desktop/unimods/is3107/project/.venv/lib/python3.11/site-packages/urllib3/util/ssl_.py", line 460, in ssl_wrap_socket
    ssl_sock = _ssl_wrap_socket_impl(sock, context, tls_in_tls, server_hostname)
               ^^^^^^^^^^^^^^^^^^^^^^^^^^^^^^^^^^^^^^^^^^^^^^^^^^^^^^^^^^^^^^^^^
  File "/Users/ervinyeoh/Desktop/unimods/is3107/project/.venv/lib/python3.11/site-packages/urllib3/util/ssl_.py", line 504, in _ssl_wrap_socket_impl
    return ssl_context.wrap_socket(sock, server_hostname=server_hostname)
           ^^^^^^^^^^^^^^^^^^^^^^^^^^^^^^^^^^^^^^^^^^^^^^^^^^^^^^^^^^^^^^
  File "/Library/Frameworks/Python.framework/Versions/3.11/lib/python3.11/ssl.py", line 517, in wrap_socket
    return self.sslsocket_class._create(
           ^^^^^^^^^^^^^^^^^^^^^^^^^^^^^
  File "/Library/Frameworks/Python.framework/Versions/3.11/lib/python3.11/ssl.py", line 1108, in _create
    self.do_handshake()
  File "/Library/Frameworks/Python.framework/Versions/3.11/lib/python3.11/ssl.py", line 1379, in do_handshake
    self._sslobj.do_handshake()
ConnectionResetError: [Errno 54] Connection reset by peer

During handling of the above exception, another exception occurred:

Traceback (most recent call last):
  File "/Users/ervinyeoh/Desktop/unimods/is3107/project/.venv/lib/python3.11/site-packages/requests/adapters.py", line 667, in send
    resp = conn.urlopen(
           ^^^^^^^^^^^^^
  File "/Users/ervinyeoh/Desktop/unimods/is3107/project/.venv/lib/python3.11/site-packages/urllib3/connectionpool.py", line 841, in urlopen
    retries = retries.increment(
              ^^^^^^^^^^^^^^^^^^
  File "/Users/ervinyeoh/Desktop/unimods/is3107/project/.venv/lib/python3.11/site-packages/urllib3/util/retry.py", line 474, in increment
    raise reraise(type(error), error, _stacktrace)
          ^^^^^^^^^^^^^^^^^^^^^^^^^^^^^^^^^^^^^^^^
  File "/Users/ervinyeoh/Desktop/unimods/is3107/project/.venv/lib/python3.11/site-packages/urllib3/util/util.py", line 38, in reraise
    raise value.with_traceback(tb)
  File "/Users/ervinyeoh/Desktop/unimods/is3107/project/.venv/lib/python3.11/site-packages/urllib3/connectionpool.py", line 787, in urlopen
    response = self._make_request(
               ^^^^^^^^^^^^^^^^^^^
  File "/Users/ervinyeoh/Desktop/unimods/is3107/project/.venv/lib/python3.11/site-packages/urllib3/connectionpool.py", line 488, in _make_request
    raise new_e
  File "/Users/ervinyeoh/Desktop/unimods/is3107/project/.venv/lib/python3.11/site-packages/urllib3/connectionpool.py", line 464, in _make_request
    self._validate_conn(conn)
  File "/Users/ervinyeoh/Desktop/unimods/is3107/project/.venv/lib/python3.11/site-packages/urllib3/connectionpool.py", line 1093, in _validate_conn
    conn.connect()
  File "/Users/ervinyeoh/Desktop/unimods/is3107/project/.venv/lib/python3.11/site-packages/urllib3/connection.py", line 741, in connect
    sock_and_verified = _ssl_wrap_socket_and_match_hostname(
                        ^^^^^^^^^^^^^^^^^^^^^^^^^^^^^^^^^^^^
  File "/Users/ervinyeoh/Desktop/unimods/is3107/project/.venv/lib/python3.11/site-packages/urllib3/connection.py", line 920, in _ssl_wrap_socket_and_match_hostname
    ssl_sock = ssl_wrap_socket(
               ^^^^^^^^^^^^^^^^
  File "/Users/ervinyeoh/Desktop/unimods/is3107/project/.venv/lib/python3.11/site-packages/urllib3/util/ssl_.py", line 460, in ssl_wrap_socket
    ssl_sock = _ssl_wrap_socket_impl(sock, context, tls_in_tls, server_hostname)
               ^^^^^^^^^^^^^^^^^^^^^^^^^^^^^^^^^^^^^^^^^^^^^^^^^^^^^^^^^^^^^^^^^
  File "/Users/ervinyeoh/Desktop/unimods/is3107/project/.venv/lib/python3.11/site-packages/urllib3/util/ssl_.py", line 504, in _ssl_wrap_socket_impl
    return ssl_context.wrap_socket(sock, server_hostname=server_hostname)
           ^^^^^^^^^^^^^^^^^^^^^^^^^^^^^^^^^^^^^^^^^^^^^^^^^^^^^^^^^^^^^^
  File "/Library/Frameworks/Python.framework/Versions/3.11/lib/python3.11/ssl.py", line 517, in wrap_socket
    return self.sslsocket_class._create(
           ^^^^^^^^^^^^^^^^^^^^^^^^^^^^^
  File "/Library/Frameworks/Python.framework/Versions/3.11/lib/python3.11/ssl.py", line 1108, in _create
    self.do_handshake()
  File "/Library/Frameworks/Python.framework/Versions/3.11/lib/python3.11/ssl.py", line 1379, in do_handshake
    self._sslobj.do_handshake()
urllib3.exceptions.ProtocolError: ('Connection aborted.', ConnectionResetError(54, 'Connection reset by peer'))

During handling of the above exception, another exception occurred:

Traceback (most recent call last):
  File "/Users/ervinyeoh/Desktop/unimods/is3107/project/.venv/lib/python3.11/site-packages/airflow/models/taskinstance.py", line 768, in _execute_task
    result = _execute_callable(context=context, **execute_callable_kwargs)
             ^^^^^^^^^^^^^^^^^^^^^^^^^^^^^^^^^^^^^^^^^^^^^^^^^^^^^^^^^^^^^
  File "/Users/ervinyeoh/Desktop/unimods/is3107/project/.venv/lib/python3.11/site-packages/airflow/models/taskinstance.py", line 734, in _execute_callable
    return ExecutionCallableRunner(
           ^^^^^^^^^^^^^^^^^^^^^^^^
  File "/Users/ervinyeoh/Desktop/unimods/is3107/project/.venv/lib/python3.11/site-packages/airflow/utils/operator_helpers.py", line 252, in run
    return self.func(*args, **kwargs)
           ^^^^^^^^^^^^^^^^^^^^^^^^^^
  File "/Users/ervinyeoh/Desktop/unimods/is3107/project/.venv/lib/python3.11/site-packages/airflow/models/baseoperator.py", line 424, in wrapper
    return func(self, *args, **kwargs)
           ^^^^^^^^^^^^^^^^^^^^^^^^^^^
  File "/Users/ervinyeoh/Desktop/unimods/is3107/project/.venv/lib/python3.11/site-packages/airflow/decorators/base.py", line 266, in execute
    return_value = super().execute(context)
                   ^^^^^^^^^^^^^^^^^^^^^^^^
  File "/Users/ervinyeoh/Desktop/unimods/is3107/project/.venv/lib/python3.11/site-packages/airflow/models/baseoperator.py", line 424, in wrapper
    return func(self, *args, **kwargs)
           ^^^^^^^^^^^^^^^^^^^^^^^^^^^
  File "/Users/ervinyeoh/Desktop/unimods/is3107/project/.venv/lib/python3.11/site-packages/airflow/operators/python.py", line 238, in execute
    return_value = self.execute_callable()
                   ^^^^^^^^^^^^^^^^^^^^^^^
  File "/Users/ervinyeoh/Desktop/unimods/is3107/project/.venv/lib/python3.11/site-packages/airflow/operators/python.py", line 256, in execute_callable
    return runner.run(*self.op_args, **self.op_kwargs)
           ^^^^^^^^^^^^^^^^^^^^^^^^^^^^^^^^^^^^^^^^^^^
  File "/Users/ervinyeoh/Desktop/unimods/is3107/project/.venv/lib/python3.11/site-packages/airflow/utils/operator_helpers.py", line 252, in run
    return self.func(*args, **kwargs)
           ^^^^^^^^^^^^^^^^^^^^^^^^^^
  File "/Users/ervinyeoh/Desktop/unimods/is3107/project/airflow/dags/dag.py", line 42, in run_yf
    run_yf_scraper(tickers)
  File "/Users/ervinyeoh/Desktop/unimods/is3107/project/airflow/dags/yf_scraper.py", line 22, in run_yf_scraper
    response = requests.get(YF_API_URL, params=params)
               ^^^^^^^^^^^^^^^^^^^^^^^^^^^^^^^^^^^^^^^
  File "/Users/ervinyeoh/Desktop/unimods/is3107/project/.venv/lib/python3.11/site-packages/requests/api.py", line 73, in get
    return request("get", url, params=params, **kwargs)
           ^^^^^^^^^^^^^^^^^^^^^^^^^^^^^^^^^^^^^^^^^^^^
  File "/Users/ervinyeoh/Desktop/unimods/is3107/project/.venv/lib/python3.11/site-packages/requests/api.py", line 59, in request
    return session.request(method=method, url=url, **kwargs)
           ^^^^^^^^^^^^^^^^^^^^^^^^^^^^^^^^^^^^^^^^^^^^^^^^^
  File "/Users/ervinyeoh/Desktop/unimods/is3107/project/.venv/lib/python3.11/site-packages/requests/sessions.py", line 589, in request
    resp = self.send(prep, **send_kwargs)
           ^^^^^^^^^^^^^^^^^^^^^^^^^^^^^^
  File "/Users/ervinyeoh/Desktop/unimods/is3107/project/.venv/lib/python3.11/site-packages/requests/sessions.py", line 703, in send
    r = adapter.send(request, **kwargs)
        ^^^^^^^^^^^^^^^^^^^^^^^^^^^^^^^
  File "/Users/ervinyeoh/Desktop/unimods/is3107/project/.venv/lib/python3.11/site-packages/requests/adapters.py", line 682, in send
    raise ConnectionError(err, request=request)
requests.exceptions.ConnectionError: ('Connection aborted.', ConnectionResetError(54, 'Connection reset by peer'))
[2025-03-23T01:31:48.648+0800] {logging_mixin.py:190} INFO - Task instance in failure state
[2025-03-23T01:31:48.649+0800] {logging_mixin.py:190} INFO - Task start:2025-03-22 16:25:43.517636+00:00 end:2025-03-22 17:31:48.648049+00:00 duration:3965.130413
[2025-03-23T01:31:48.649+0800] {logging_mixin.py:190} INFO - Task:<Task(_PythonDecoratedOperator): run_yf> dag:<DAG: reddit_yf_scraper> dagrun:<DagRun reddit_yf_scraper @ 2025-03-21 16:00:00+00:00: scheduled__2025-03-21T16:00:00+00:00, state:running, queued_at: 2025-03-22 16:08:05.703245+00:00. externally triggered: False>
[2025-03-23T01:31:48.649+0800] {logging_mixin.py:190} INFO - Failure caused by ('Connection aborted.', ConnectionResetError(54, 'Connection reset by peer'))
[2025-03-23T01:31:48.650+0800] {taskinstance.py:1226} INFO - Marking task as UP_FOR_RETRY. dag_id=reddit_yf_scraper, task_id=run_yf, run_id=scheduled__2025-03-21T16:00:00+00:00, execution_date=20250321T160000, start_date=20250322T162543, end_date=20250322T173148
[2025-03-23T01:31:48.689+0800] {taskinstance.py:341} INFO - ::group::Post task execution logs
[2025-03-23T01:31:48.690+0800] {standard_task_runner.py:124} ERROR - Failed to execute job 134 for task run_yf (('Connection aborted.', ConnectionResetError(54, 'Connection reset by peer')); 95325)
Traceback (most recent call last):
  File "/Users/ervinyeoh/Desktop/unimods/is3107/project/.venv/lib/python3.11/site-packages/urllib3/connectionpool.py", line 787, in urlopen
    response = self._make_request(
               ^^^^^^^^^^^^^^^^^^^
  File "/Users/ervinyeoh/Desktop/unimods/is3107/project/.venv/lib/python3.11/site-packages/urllib3/connectionpool.py", line 488, in _make_request
    raise new_e
  File "/Users/ervinyeoh/Desktop/unimods/is3107/project/.venv/lib/python3.11/site-packages/urllib3/connectionpool.py", line 464, in _make_request
    self._validate_conn(conn)
  File "/Users/ervinyeoh/Desktop/unimods/is3107/project/.venv/lib/python3.11/site-packages/urllib3/connectionpool.py", line 1093, in _validate_conn
    conn.connect()
  File "/Users/ervinyeoh/Desktop/unimods/is3107/project/.venv/lib/python3.11/site-packages/urllib3/connection.py", line 741, in connect
    sock_and_verified = _ssl_wrap_socket_and_match_hostname(
                        ^^^^^^^^^^^^^^^^^^^^^^^^^^^^^^^^^^^^
  File "/Users/ervinyeoh/Desktop/unimods/is3107/project/.venv/lib/python3.11/site-packages/urllib3/connection.py", line 920, in _ssl_wrap_socket_and_match_hostname
    ssl_sock = ssl_wrap_socket(
               ^^^^^^^^^^^^^^^^
  File "/Users/ervinyeoh/Desktop/unimods/is3107/project/.venv/lib/python3.11/site-packages/urllib3/util/ssl_.py", line 460, in ssl_wrap_socket
    ssl_sock = _ssl_wrap_socket_impl(sock, context, tls_in_tls, server_hostname)
               ^^^^^^^^^^^^^^^^^^^^^^^^^^^^^^^^^^^^^^^^^^^^^^^^^^^^^^^^^^^^^^^^^
  File "/Users/ervinyeoh/Desktop/unimods/is3107/project/.venv/lib/python3.11/site-packages/urllib3/util/ssl_.py", line 504, in _ssl_wrap_socket_impl
    return ssl_context.wrap_socket(sock, server_hostname=server_hostname)
           ^^^^^^^^^^^^^^^^^^^^^^^^^^^^^^^^^^^^^^^^^^^^^^^^^^^^^^^^^^^^^^
  File "/Library/Frameworks/Python.framework/Versions/3.11/lib/python3.11/ssl.py", line 517, in wrap_socket
    return self.sslsocket_class._create(
           ^^^^^^^^^^^^^^^^^^^^^^^^^^^^^
  File "/Library/Frameworks/Python.framework/Versions/3.11/lib/python3.11/ssl.py", line 1108, in _create
    self.do_handshake()
  File "/Library/Frameworks/Python.framework/Versions/3.11/lib/python3.11/ssl.py", line 1379, in do_handshake
    self._sslobj.do_handshake()
ConnectionResetError: [Errno 54] Connection reset by peer

During handling of the above exception, another exception occurred:

Traceback (most recent call last):
  File "/Users/ervinyeoh/Desktop/unimods/is3107/project/.venv/lib/python3.11/site-packages/requests/adapters.py", line 667, in send
    resp = conn.urlopen(
           ^^^^^^^^^^^^^
  File "/Users/ervinyeoh/Desktop/unimods/is3107/project/.venv/lib/python3.11/site-packages/urllib3/connectionpool.py", line 841, in urlopen
    retries = retries.increment(
              ^^^^^^^^^^^^^^^^^^
  File "/Users/ervinyeoh/Desktop/unimods/is3107/project/.venv/lib/python3.11/site-packages/urllib3/util/retry.py", line 474, in increment
    raise reraise(type(error), error, _stacktrace)
          ^^^^^^^^^^^^^^^^^^^^^^^^^^^^^^^^^^^^^^^^
  File "/Users/ervinyeoh/Desktop/unimods/is3107/project/.venv/lib/python3.11/site-packages/urllib3/util/util.py", line 38, in reraise
    raise value.with_traceback(tb)
  File "/Users/ervinyeoh/Desktop/unimods/is3107/project/.venv/lib/python3.11/site-packages/urllib3/connectionpool.py", line 787, in urlopen
    response = self._make_request(
               ^^^^^^^^^^^^^^^^^^^
  File "/Users/ervinyeoh/Desktop/unimods/is3107/project/.venv/lib/python3.11/site-packages/urllib3/connectionpool.py", line 488, in _make_request
    raise new_e
  File "/Users/ervinyeoh/Desktop/unimods/is3107/project/.venv/lib/python3.11/site-packages/urllib3/connectionpool.py", line 464, in _make_request
    self._validate_conn(conn)
  File "/Users/ervinyeoh/Desktop/unimods/is3107/project/.venv/lib/python3.11/site-packages/urllib3/connectionpool.py", line 1093, in _validate_conn
    conn.connect()
  File "/Users/ervinyeoh/Desktop/unimods/is3107/project/.venv/lib/python3.11/site-packages/urllib3/connection.py", line 741, in connect
    sock_and_verified = _ssl_wrap_socket_and_match_hostname(
                        ^^^^^^^^^^^^^^^^^^^^^^^^^^^^^^^^^^^^
  File "/Users/ervinyeoh/Desktop/unimods/is3107/project/.venv/lib/python3.11/site-packages/urllib3/connection.py", line 920, in _ssl_wrap_socket_and_match_hostname
    ssl_sock = ssl_wrap_socket(
               ^^^^^^^^^^^^^^^^
  File "/Users/ervinyeoh/Desktop/unimods/is3107/project/.venv/lib/python3.11/site-packages/urllib3/util/ssl_.py", line 460, in ssl_wrap_socket
    ssl_sock = _ssl_wrap_socket_impl(sock, context, tls_in_tls, server_hostname)
               ^^^^^^^^^^^^^^^^^^^^^^^^^^^^^^^^^^^^^^^^^^^^^^^^^^^^^^^^^^^^^^^^^
  File "/Users/ervinyeoh/Desktop/unimods/is3107/project/.venv/lib/python3.11/site-packages/urllib3/util/ssl_.py", line 504, in _ssl_wrap_socket_impl
    return ssl_context.wrap_socket(sock, server_hostname=server_hostname)
           ^^^^^^^^^^^^^^^^^^^^^^^^^^^^^^^^^^^^^^^^^^^^^^^^^^^^^^^^^^^^^^
  File "/Library/Frameworks/Python.framework/Versions/3.11/lib/python3.11/ssl.py", line 517, in wrap_socket
    return self.sslsocket_class._create(
           ^^^^^^^^^^^^^^^^^^^^^^^^^^^^^
  File "/Library/Frameworks/Python.framework/Versions/3.11/lib/python3.11/ssl.py", line 1108, in _create
    self.do_handshake()
  File "/Library/Frameworks/Python.framework/Versions/3.11/lib/python3.11/ssl.py", line 1379, in do_handshake
    self._sslobj.do_handshake()
urllib3.exceptions.ProtocolError: ('Connection aborted.', ConnectionResetError(54, 'Connection reset by peer'))

During handling of the above exception, another exception occurred:

Traceback (most recent call last):
  File "/Users/ervinyeoh/Desktop/unimods/is3107/project/.venv/lib/python3.11/site-packages/airflow/task/task_runner/standard_task_runner.py", line 117, in _start_by_fork
    ret = args.func(args, dag=self.dag)
          ^^^^^^^^^^^^^^^^^^^^^^^^^^^^^
  File "/Users/ervinyeoh/Desktop/unimods/is3107/project/.venv/lib/python3.11/site-packages/airflow/cli/cli_config.py", line 49, in command
    return func(*args, **kwargs)
           ^^^^^^^^^^^^^^^^^^^^^
  File "/Users/ervinyeoh/Desktop/unimods/is3107/project/.venv/lib/python3.11/site-packages/airflow/utils/cli.py", line 116, in wrapper
    return f(*args, **kwargs)
           ^^^^^^^^^^^^^^^^^^
  File "/Users/ervinyeoh/Desktop/unimods/is3107/project/.venv/lib/python3.11/site-packages/airflow/cli/commands/task_command.py", line 483, in task_run
    task_return_code = _run_task_by_selected_method(args, _dag, ti)
                       ^^^^^^^^^^^^^^^^^^^^^^^^^^^^^^^^^^^^^^^^^^^^
  File "/Users/ervinyeoh/Desktop/unimods/is3107/project/.venv/lib/python3.11/site-packages/airflow/cli/commands/task_command.py", line 256, in _run_task_by_selected_method
    return _run_raw_task(args, ti)
           ^^^^^^^^^^^^^^^^^^^^^^^
  File "/Users/ervinyeoh/Desktop/unimods/is3107/project/.venv/lib/python3.11/site-packages/airflow/cli/commands/task_command.py", line 341, in _run_raw_task
    return ti._run_raw_task(
           ^^^^^^^^^^^^^^^^^
  File "/Users/ervinyeoh/Desktop/unimods/is3107/project/.venv/lib/python3.11/site-packages/airflow/utils/session.py", line 97, in wrapper
    return func(*args, session=session, **kwargs)
           ^^^^^^^^^^^^^^^^^^^^^^^^^^^^^^^^^^^^^^
  File "/Users/ervinyeoh/Desktop/unimods/is3107/project/.venv/lib/python3.11/site-packages/airflow/models/taskinstance.py", line 3006, in _run_raw_task
    return _run_raw_task(
           ^^^^^^^^^^^^^^
  File "/Users/ervinyeoh/Desktop/unimods/is3107/project/.venv/lib/python3.11/site-packages/airflow/models/taskinstance.py", line 274, in _run_raw_task
    TaskInstance._execute_task_with_callbacks(
  File "/Users/ervinyeoh/Desktop/unimods/is3107/project/.venv/lib/python3.11/site-packages/airflow/models/taskinstance.py", line 3161, in _execute_task_with_callbacks
    result = self._execute_task(context, task_orig)
             ^^^^^^^^^^^^^^^^^^^^^^^^^^^^^^^^^^^^^^
  File "/Users/ervinyeoh/Desktop/unimods/is3107/project/.venv/lib/python3.11/site-packages/airflow/models/taskinstance.py", line 3185, in _execute_task
    return _execute_task(self, context, task_orig)
           ^^^^^^^^^^^^^^^^^^^^^^^^^^^^^^^^^^^^^^^
  File "/Users/ervinyeoh/Desktop/unimods/is3107/project/.venv/lib/python3.11/site-packages/airflow/models/taskinstance.py", line 768, in _execute_task
    result = _execute_callable(context=context, **execute_callable_kwargs)
             ^^^^^^^^^^^^^^^^^^^^^^^^^^^^^^^^^^^^^^^^^^^^^^^^^^^^^^^^^^^^^
  File "/Users/ervinyeoh/Desktop/unimods/is3107/project/.venv/lib/python3.11/site-packages/airflow/models/taskinstance.py", line 734, in _execute_callable
    return ExecutionCallableRunner(
           ^^^^^^^^^^^^^^^^^^^^^^^^
  File "/Users/ervinyeoh/Desktop/unimods/is3107/project/.venv/lib/python3.11/site-packages/airflow/utils/operator_helpers.py", line 252, in run
    return self.func(*args, **kwargs)
           ^^^^^^^^^^^^^^^^^^^^^^^^^^
  File "/Users/ervinyeoh/Desktop/unimods/is3107/project/.venv/lib/python3.11/site-packages/airflow/models/baseoperator.py", line 424, in wrapper
    return func(self, *args, **kwargs)
           ^^^^^^^^^^^^^^^^^^^^^^^^^^^
  File "/Users/ervinyeoh/Desktop/unimods/is3107/project/.venv/lib/python3.11/site-packages/airflow/decorators/base.py", line 266, in execute
    return_value = super().execute(context)
                   ^^^^^^^^^^^^^^^^^^^^^^^^
  File "/Users/ervinyeoh/Desktop/unimods/is3107/project/.venv/lib/python3.11/site-packages/airflow/models/baseoperator.py", line 424, in wrapper
    return func(self, *args, **kwargs)
           ^^^^^^^^^^^^^^^^^^^^^^^^^^^
  File "/Users/ervinyeoh/Desktop/unimods/is3107/project/.venv/lib/python3.11/site-packages/airflow/operators/python.py", line 238, in execute
    return_value = self.execute_callable()
                   ^^^^^^^^^^^^^^^^^^^^^^^
  File "/Users/ervinyeoh/Desktop/unimods/is3107/project/.venv/lib/python3.11/site-packages/airflow/operators/python.py", line 256, in execute_callable
    return runner.run(*self.op_args, **self.op_kwargs)
           ^^^^^^^^^^^^^^^^^^^^^^^^^^^^^^^^^^^^^^^^^^^
  File "/Users/ervinyeoh/Desktop/unimods/is3107/project/.venv/lib/python3.11/site-packages/airflow/utils/operator_helpers.py", line 252, in run
    return self.func(*args, **kwargs)
           ^^^^^^^^^^^^^^^^^^^^^^^^^^
  File "/Users/ervinyeoh/Desktop/unimods/is3107/project/airflow/dags/dag.py", line 42, in run_yf
    run_yf_scraper(tickers)
  File "/Users/ervinyeoh/Desktop/unimods/is3107/project/airflow/dags/yf_scraper.py", line 22, in run_yf_scraper
    response = requests.get(YF_API_URL, params=params)
               ^^^^^^^^^^^^^^^^^^^^^^^^^^^^^^^^^^^^^^^
  File "/Users/ervinyeoh/Desktop/unimods/is3107/project/.venv/lib/python3.11/site-packages/requests/api.py", line 73, in get
    return request("get", url, params=params, **kwargs)
           ^^^^^^^^^^^^^^^^^^^^^^^^^^^^^^^^^^^^^^^^^^^^
  File "/Users/ervinyeoh/Desktop/unimods/is3107/project/.venv/lib/python3.11/site-packages/requests/api.py", line 59, in request
    return session.request(method=method, url=url, **kwargs)
           ^^^^^^^^^^^^^^^^^^^^^^^^^^^^^^^^^^^^^^^^^^^^^^^^^
  File "/Users/ervinyeoh/Desktop/unimods/is3107/project/.venv/lib/python3.11/site-packages/requests/sessions.py", line 589, in request
    resp = self.send(prep, **send_kwargs)
           ^^^^^^^^^^^^^^^^^^^^^^^^^^^^^^
  File "/Users/ervinyeoh/Desktop/unimods/is3107/project/.venv/lib/python3.11/site-packages/requests/sessions.py", line 703, in send
    r = adapter.send(request, **kwargs)
        ^^^^^^^^^^^^^^^^^^^^^^^^^^^^^^^
  File "/Users/ervinyeoh/Desktop/unimods/is3107/project/.venv/lib/python3.11/site-packages/requests/adapters.py", line 682, in send
    raise ConnectionError(err, request=request)
requests.exceptions.ConnectionError: ('Connection aborted.', ConnectionResetError(54, 'Connection reset by peer'))
[2025-03-23T01:31:48.732+0800] {local_task_job_runner.py:266} INFO - Task exited with return code 1
[2025-03-23T01:31:48.749+0800] {taskinstance.py:3901} INFO - 0 downstream tasks scheduled from follow-on schedule check
[2025-03-23T01:31:48.750+0800] {local_task_job_runner.py:245} INFO - ::endgroup::
