[2025-04-02T11:52:46.385+0800] {local_task_job_runner.py:123} INFO - ::group::Pre task execution logs
[2025-04-02T11:52:46.393+0800] {taskinstance.py:2614} INFO - Dependencies all met for dep_context=non-requeueable deps ti=<TaskInstance: reddit_yf_scraper.download_reddit_from_gcs manual__2025-04-02T03:44:46.385060+00:00 [queued]>
[2025-04-02T11:52:46.397+0800] {taskinstance.py:2614} INFO - Dependencies all met for dep_context=requeueable deps ti=<TaskInstance: reddit_yf_scraper.download_reddit_from_gcs manual__2025-04-02T03:44:46.385060+00:00 [queued]>
[2025-04-02T11:52:46.397+0800] {taskinstance.py:2867} INFO - Starting attempt 2 of 2
[2025-04-02T11:52:46.404+0800] {taskinstance.py:2890} INFO - Executing <Task(GCSToLocalFilesystemOperator): download_reddit_from_gcs> on 2025-04-02 03:44:46.385060+00:00
[2025-04-02T11:52:46.407+0800] {standard_task_runner.py:72} INFO - Started process 22609 to run task
[2025-04-02T11:52:46.410+0800] {standard_task_runner.py:104} INFO - Running: ['airflow', 'tasks', 'run', 'reddit_yf_scraper', 'download_reddit_from_gcs', 'manual__2025-04-02T03:44:46.385060+00:00', '--job-id', '192', '--raw', '--subdir', 'DAGS_FOLDER/dag.py', '--cfg-path', '/var/folders/xg/h9xj0trn3dxds251bj2q6hf80000gn/T/tmp580s4z0q']
[2025-04-02T11:52:46.411+0800] {standard_task_runner.py:105} INFO - Job 192: Subtask download_reddit_from_gcs
[2025-04-02T11:52:46.445+0800] {task_command.py:467} INFO - Running <TaskInstance: reddit_yf_scraper.download_reddit_from_gcs manual__2025-04-02T03:44:46.385060+00:00 [running]> on host ervins-macbook-air-2.local
[2025-04-02T11:52:46.476+0800] {taskinstance.py:3134} INFO - Exporting env vars: AIRFLOW_CTX_DAG_OWNER='airflow' AIRFLOW_CTX_DAG_ID='reddit_yf_scraper' AIRFLOW_CTX_TASK_ID='download_reddit_from_gcs' AIRFLOW_CTX_EXECUTION_DATE='2025-04-02T03:44:46.385060+00:00' AIRFLOW_CTX_TRY_NUMBER='2' AIRFLOW_CTX_DAG_RUN_ID='manual__2025-04-02T03:44:46.385060+00:00'
[2025-04-02T11:52:46.477+0800] {logging_mixin.py:190} INFO - Task instance is in running state
[2025-04-02T11:52:46.477+0800] {logging_mixin.py:190} INFO -  Previous state of the Task instance: queued
[2025-04-02T11:52:46.478+0800] {logging_mixin.py:190} INFO - Current task name:download_reddit_from_gcs state:running start_date:2025-04-02 03:52:46.393957+00:00
[2025-04-02T11:52:46.478+0800] {logging_mixin.py:190} INFO - Dag name:reddit_yf_scraper and current dag run status:running
[2025-04-02T11:52:46.478+0800] {taskinstance.py:732} INFO - ::endgroup::
[2025-04-02T11:52:46.478+0800] {gcs_to_local.py:101} INFO - Executing download: my-data-is3107, reddit-test/*.csv, /Users/ervinyeoh/Desktop/unimods/is3107/project/airflow/downloads/reddit_2025-04-02.csv
[2025-04-02T11:52:46.482+0800] {connection.py:277} WARNING - Connection schemes (type: google_cloud_platform) shall not contain '_' according to RFC3986.
[2025-04-02T11:52:46.484+0800] {base.py:84} INFO - Retrieving connection 'google_cloud_default'
[2025-04-02T11:52:48.054+0800] {gcs.py:370} ERROR - Download attempt of object: reddit-test/*.csv from my-data-is3107 has failed. Attempt: 0, max 1.
[2025-04-02T11:52:48.055+0800] {taskinstance.py:3313} ERROR - Task failed with exception
Traceback (most recent call last):
  File "/Users/ervinyeoh/Desktop/unimods/is3107/project/.venv/lib/python3.11/site-packages/google/cloud/storage/blob.py", line 4423, in _prep_and_do_download
    self._do_download(
  File "/Users/ervinyeoh/Desktop/unimods/is3107/project/.venv/lib/python3.11/site-packages/google/cloud/storage/blob.py", line 1045, in _do_download
    response = download.consume(transport, timeout=timeout)
               ^^^^^^^^^^^^^^^^^^^^^^^^^^^^^^^^^^^^^^^^^^^^
  File "/Users/ervinyeoh/Desktop/unimods/is3107/project/.venv/lib/python3.11/site-packages/google/resumable_media/requests/download.py", line 263, in consume
    return _request_helpers.wait_and_retry(
           ^^^^^^^^^^^^^^^^^^^^^^^^^^^^^^^^
  File "/Users/ervinyeoh/Desktop/unimods/is3107/project/.venv/lib/python3.11/site-packages/google/resumable_media/requests/_request_helpers.py", line 155, in wait_and_retry
    response = func()
               ^^^^^^
  File "/Users/ervinyeoh/Desktop/unimods/is3107/project/.venv/lib/python3.11/site-packages/google/resumable_media/requests/download.py", line 245, in retriable_request
    self._process_response(result)
  File "/Users/ervinyeoh/Desktop/unimods/is3107/project/.venv/lib/python3.11/site-packages/google/resumable_media/_download.py", line 188, in _process_response
    _helpers.require_status_code(
  File "/Users/ervinyeoh/Desktop/unimods/is3107/project/.venv/lib/python3.11/site-packages/google/resumable_media/_helpers.py", line 108, in require_status_code
    raise common.InvalidResponse(
google.resumable_media.common.InvalidResponse: ('Request failed with status code', 404, 'Expected one of', 200, 206)

During handling of the above exception, another exception occurred:

Traceback (most recent call last):
  File "/Users/ervinyeoh/Desktop/unimods/is3107/project/.venv/lib/python3.11/site-packages/airflow/models/taskinstance.py", line 768, in _execute_task
    result = _execute_callable(context=context, **execute_callable_kwargs)
             ^^^^^^^^^^^^^^^^^^^^^^^^^^^^^^^^^^^^^^^^^^^^^^^^^^^^^^^^^^^^^
  File "/Users/ervinyeoh/Desktop/unimods/is3107/project/.venv/lib/python3.11/site-packages/airflow/models/taskinstance.py", line 734, in _execute_callable
    return ExecutionCallableRunner(
           ^^^^^^^^^^^^^^^^^^^^^^^^
  File "/Users/ervinyeoh/Desktop/unimods/is3107/project/.venv/lib/python3.11/site-packages/airflow/utils/operator_helpers.py", line 252, in run
    return self.func(*args, **kwargs)
           ^^^^^^^^^^^^^^^^^^^^^^^^^^
  File "/Users/ervinyeoh/Desktop/unimods/is3107/project/.venv/lib/python3.11/site-packages/airflow/models/baseoperator.py", line 424, in wrapper
    return func(self, *args, **kwargs)
           ^^^^^^^^^^^^^^^^^^^^^^^^^^^
  File "/Users/ervinyeoh/Desktop/unimods/is3107/project/.venv/lib/python3.11/site-packages/airflow/providers/google/cloud/transfers/gcs_to_local.py", line 115, in execute
    hook.download(bucket_name=self.bucket, object_name=self.object_name, filename=self.filename)
  File "/Users/ervinyeoh/Desktop/unimods/is3107/project/.venv/lib/python3.11/site-packages/airflow/providers/google/cloud/hooks/gcs.py", line 353, in download
    blob.download_to_filename(filename, timeout=timeout)
  File "/Library/Frameworks/Python.framework/Versions/3.11/lib/python3.11/contextlib.py", line 81, in inner
    return func(*args, **kwds)
           ^^^^^^^^^^^^^^^^^^^
  File "/Users/ervinyeoh/Desktop/unimods/is3107/project/.venv/lib/python3.11/site-packages/google/cloud/storage/blob.py", line 1349, in download_to_filename
    self._handle_filename_and_download(
  File "/Users/ervinyeoh/Desktop/unimods/is3107/project/.venv/lib/python3.11/site-packages/google/cloud/storage/blob.py", line 1224, in _handle_filename_and_download
    self._prep_and_do_download(
  File "/Users/ervinyeoh/Desktop/unimods/is3107/project/.venv/lib/python3.11/site-packages/google/cloud/storage/blob.py", line 4436, in _prep_and_do_download
    _raise_from_invalid_response(exc)
  File "/Users/ervinyeoh/Desktop/unimods/is3107/project/.venv/lib/python3.11/site-packages/google/cloud/storage/blob.py", line 4908, in _raise_from_invalid_response
    raise exceptions.from_http_status(response.status_code, message, response=response)
google.api_core.exceptions.NotFound: 404 GET https://storage.googleapis.com/download/storage/v1/b/my-data-is3107/o/reddit-test%2F%2A.csv?alt=media: No such object: my-data-is3107/reddit-test/*.csv: ('Request failed with status code', 404, 'Expected one of', <HTTPStatus.OK: 200>, <HTTPStatus.PARTIAL_CONTENT: 206>)
[2025-04-02T11:52:48.066+0800] {logging_mixin.py:190} INFO - Task instance in failure state
[2025-04-02T11:52:48.067+0800] {logging_mixin.py:190} INFO - Task start:2025-04-02 03:52:46.393957+00:00 end:2025-04-02 03:52:48.066463+00:00 duration:1.672506
[2025-04-02T11:52:48.067+0800] {logging_mixin.py:190} INFO - Task:<Task(GCSToLocalFilesystemOperator): download_reddit_from_gcs> dag:<DAG: reddit_yf_scraper> dagrun:<DagRun reddit_yf_scraper @ 2025-04-02 03:44:46.385060+00:00: manual__2025-04-02T03:44:46.385060+00:00, state:running, queued_at: 2025-04-02 03:44:46.406902+00:00. externally triggered: True>
[2025-04-02T11:52:48.067+0800] {logging_mixin.py:190} INFO - Failure caused by 404 GET https://storage.googleapis.com/download/storage/v1/b/my-data-is3107/o/reddit-test%2F%2A.csv?alt=media: No such object: my-data-is3107/reddit-test/*.csv: ('Request failed with status code', 404, 'Expected one of', <HTTPStatus.OK: 200>, <HTTPStatus.PARTIAL_CONTENT: 206>)
[2025-04-02T11:52:48.068+0800] {taskinstance.py:1226} INFO - Marking task as FAILED. dag_id=reddit_yf_scraper, task_id=download_reddit_from_gcs, run_id=manual__2025-04-02T03:44:46.385060+00:00, execution_date=20250402T034446, start_date=20250402T035246, end_date=20250402T035248
[2025-04-02T11:52:48.076+0800] {taskinstance.py:341} INFO - ::group::Post task execution logs
[2025-04-02T11:52:48.076+0800] {standard_task_runner.py:124} ERROR - Failed to execute job 192 for task download_reddit_from_gcs (404 GET https://storage.googleapis.com/download/storage/v1/b/my-data-is3107/o/reddit-test%2F%2A.csv?alt=media: No such object: my-data-is3107/reddit-test/*.csv: ('Request failed with status code', 404, 'Expected one of', <HTTPStatus.OK: 200>, <HTTPStatus.PARTIAL_CONTENT: 206>); 22609)
Traceback (most recent call last):
  File "/Users/ervinyeoh/Desktop/unimods/is3107/project/.venv/lib/python3.11/site-packages/google/cloud/storage/blob.py", line 4423, in _prep_and_do_download
    self._do_download(
  File "/Users/ervinyeoh/Desktop/unimods/is3107/project/.venv/lib/python3.11/site-packages/google/cloud/storage/blob.py", line 1045, in _do_download
    response = download.consume(transport, timeout=timeout)
               ^^^^^^^^^^^^^^^^^^^^^^^^^^^^^^^^^^^^^^^^^^^^
  File "/Users/ervinyeoh/Desktop/unimods/is3107/project/.venv/lib/python3.11/site-packages/google/resumable_media/requests/download.py", line 263, in consume
    return _request_helpers.wait_and_retry(
           ^^^^^^^^^^^^^^^^^^^^^^^^^^^^^^^^
  File "/Users/ervinyeoh/Desktop/unimods/is3107/project/.venv/lib/python3.11/site-packages/google/resumable_media/requests/_request_helpers.py", line 155, in wait_and_retry
    response = func()
               ^^^^^^
  File "/Users/ervinyeoh/Desktop/unimods/is3107/project/.venv/lib/python3.11/site-packages/google/resumable_media/requests/download.py", line 245, in retriable_request
    self._process_response(result)
  File "/Users/ervinyeoh/Desktop/unimods/is3107/project/.venv/lib/python3.11/site-packages/google/resumable_media/_download.py", line 188, in _process_response
    _helpers.require_status_code(
  File "/Users/ervinyeoh/Desktop/unimods/is3107/project/.venv/lib/python3.11/site-packages/google/resumable_media/_helpers.py", line 108, in require_status_code
    raise common.InvalidResponse(
google.resumable_media.common.InvalidResponse: ('Request failed with status code', 404, 'Expected one of', 200, 206)

During handling of the above exception, another exception occurred:

Traceback (most recent call last):
  File "/Users/ervinyeoh/Desktop/unimods/is3107/project/.venv/lib/python3.11/site-packages/airflow/task/task_runner/standard_task_runner.py", line 117, in _start_by_fork
    ret = args.func(args, dag=self.dag)
          ^^^^^^^^^^^^^^^^^^^^^^^^^^^^^
  File "/Users/ervinyeoh/Desktop/unimods/is3107/project/.venv/lib/python3.11/site-packages/airflow/cli/cli_config.py", line 49, in command
    return func(*args, **kwargs)
           ^^^^^^^^^^^^^^^^^^^^^
  File "/Users/ervinyeoh/Desktop/unimods/is3107/project/.venv/lib/python3.11/site-packages/airflow/utils/cli.py", line 116, in wrapper
    return f(*args, **kwargs)
           ^^^^^^^^^^^^^^^^^^
  File "/Users/ervinyeoh/Desktop/unimods/is3107/project/.venv/lib/python3.11/site-packages/airflow/cli/commands/task_command.py", line 483, in task_run
    task_return_code = _run_task_by_selected_method(args, _dag, ti)
                       ^^^^^^^^^^^^^^^^^^^^^^^^^^^^^^^^^^^^^^^^^^^^
  File "/Users/ervinyeoh/Desktop/unimods/is3107/project/.venv/lib/python3.11/site-packages/airflow/cli/commands/task_command.py", line 256, in _run_task_by_selected_method
    return _run_raw_task(args, ti)
           ^^^^^^^^^^^^^^^^^^^^^^^
  File "/Users/ervinyeoh/Desktop/unimods/is3107/project/.venv/lib/python3.11/site-packages/airflow/cli/commands/task_command.py", line 341, in _run_raw_task
    return ti._run_raw_task(
           ^^^^^^^^^^^^^^^^^
  File "/Users/ervinyeoh/Desktop/unimods/is3107/project/.venv/lib/python3.11/site-packages/airflow/utils/session.py", line 97, in wrapper
    return func(*args, session=session, **kwargs)
           ^^^^^^^^^^^^^^^^^^^^^^^^^^^^^^^^^^^^^^
  File "/Users/ervinyeoh/Desktop/unimods/is3107/project/.venv/lib/python3.11/site-packages/airflow/models/taskinstance.py", line 3006, in _run_raw_task
    return _run_raw_task(
           ^^^^^^^^^^^^^^
  File "/Users/ervinyeoh/Desktop/unimods/is3107/project/.venv/lib/python3.11/site-packages/airflow/models/taskinstance.py", line 274, in _run_raw_task
    TaskInstance._execute_task_with_callbacks(
  File "/Users/ervinyeoh/Desktop/unimods/is3107/project/.venv/lib/python3.11/site-packages/airflow/models/taskinstance.py", line 3161, in _execute_task_with_callbacks
    result = self._execute_task(context, task_orig)
             ^^^^^^^^^^^^^^^^^^^^^^^^^^^^^^^^^^^^^^
  File "/Users/ervinyeoh/Desktop/unimods/is3107/project/.venv/lib/python3.11/site-packages/airflow/models/taskinstance.py", line 3185, in _execute_task
    return _execute_task(self, context, task_orig)
           ^^^^^^^^^^^^^^^^^^^^^^^^^^^^^^^^^^^^^^^
  File "/Users/ervinyeoh/Desktop/unimods/is3107/project/.venv/lib/python3.11/site-packages/airflow/models/taskinstance.py", line 768, in _execute_task
    result = _execute_callable(context=context, **execute_callable_kwargs)
             ^^^^^^^^^^^^^^^^^^^^^^^^^^^^^^^^^^^^^^^^^^^^^^^^^^^^^^^^^^^^^
  File "/Users/ervinyeoh/Desktop/unimods/is3107/project/.venv/lib/python3.11/site-packages/airflow/models/taskinstance.py", line 734, in _execute_callable
    return ExecutionCallableRunner(
           ^^^^^^^^^^^^^^^^^^^^^^^^
  File "/Users/ervinyeoh/Desktop/unimods/is3107/project/.venv/lib/python3.11/site-packages/airflow/utils/operator_helpers.py", line 252, in run
    return self.func(*args, **kwargs)
           ^^^^^^^^^^^^^^^^^^^^^^^^^^
  File "/Users/ervinyeoh/Desktop/unimods/is3107/project/.venv/lib/python3.11/site-packages/airflow/models/baseoperator.py", line 424, in wrapper
    return func(self, *args, **kwargs)
           ^^^^^^^^^^^^^^^^^^^^^^^^^^^
  File "/Users/ervinyeoh/Desktop/unimods/is3107/project/.venv/lib/python3.11/site-packages/airflow/providers/google/cloud/transfers/gcs_to_local.py", line 115, in execute
    hook.download(bucket_name=self.bucket, object_name=self.object_name, filename=self.filename)
  File "/Users/ervinyeoh/Desktop/unimods/is3107/project/.venv/lib/python3.11/site-packages/airflow/providers/google/cloud/hooks/gcs.py", line 353, in download
    blob.download_to_filename(filename, timeout=timeout)
  File "/Library/Frameworks/Python.framework/Versions/3.11/lib/python3.11/contextlib.py", line 81, in inner
    return func(*args, **kwds)
           ^^^^^^^^^^^^^^^^^^^
  File "/Users/ervinyeoh/Desktop/unimods/is3107/project/.venv/lib/python3.11/site-packages/google/cloud/storage/blob.py", line 1349, in download_to_filename
    self._handle_filename_and_download(
  File "/Users/ervinyeoh/Desktop/unimods/is3107/project/.venv/lib/python3.11/site-packages/google/cloud/storage/blob.py", line 1224, in _handle_filename_and_download
    self._prep_and_do_download(
  File "/Users/ervinyeoh/Desktop/unimods/is3107/project/.venv/lib/python3.11/site-packages/google/cloud/storage/blob.py", line 4436, in _prep_and_do_download
    _raise_from_invalid_response(exc)
  File "/Users/ervinyeoh/Desktop/unimods/is3107/project/.venv/lib/python3.11/site-packages/google/cloud/storage/blob.py", line 4908, in _raise_from_invalid_response
    raise exceptions.from_http_status(response.status_code, message, response=response)
google.api_core.exceptions.NotFound: 404 GET https://storage.googleapis.com/download/storage/v1/b/my-data-is3107/o/reddit-test%2F%2A.csv?alt=media: No such object: my-data-is3107/reddit-test/*.csv: ('Request failed with status code', 404, 'Expected one of', <HTTPStatus.OK: 200>, <HTTPStatus.PARTIAL_CONTENT: 206>)
[2025-04-02T11:52:48.096+0800] {local_task_job_runner.py:266} INFO - Task exited with return code 1
[2025-04-02T11:52:48.105+0800] {taskinstance.py:3901} INFO - 0 downstream tasks scheduled from follow-on schedule check
[2025-04-02T11:52:48.105+0800] {local_task_job_runner.py:245} INFO - ::endgroup::
